Workbook
Name Respuesta: 'T1-T2-T4 Matriz Riesgos '!$D$138:$D$143
Name Riesgo: 'T1-T2-T4 Matriz Riesgos '!$B$138:$B$142

Sheet Portada y Rúbrica Talleres
C6: Plantilla para trabajo de Talleres
C7: Equipo de Trabajo N° | D7: X
C8: Integrantes del Grupo de Trabajo:
B9: 1.
B10: 2.
B11: 3.
B12: 4.
B13: 5.
B14: 6.
B15: 7.
C17: Rúbrica Talleres Módulo 5.1: Gestión de Riesgos en Proyectos
C20: Concepto evaluado | D20: Puntaje | E20: Puntaje obtenido | F20: OBSERVACIONES
C21: Taller 1.Identificación y Registro de Riesgos del Proyecto (Matriz de Riesgos de Proyecto)
C22: Completa recuadros superiores de la Matriz de Riesgos (identificación del proyecto con todos sus aspectos, CAPEX, clase de estimación y moneda) | D22: 1
C23: Diseñar una RBS . Considerando en ella los tipos de riesgos (no los eventos) posibles de ocurrir en el proyecto | D23: 1
C24: En la Matriz , identificar y caracterizar 8 riesgos relevantes de distinta categoría (en función de RBS anterior) en base a WBS del Proyecto (debe incluirse en listas desplegables) y en relación al caso de estudio de cada proyecto de todas las fases . Para el taller integral deberan definirse 16 riesgos. | D24: 2
C25: Consideración de Causas de diversa naturaleza y distintos tipos de impactos. | D25: 1
C26: Definir controles existentes en WBS y PEP del proyecto | D26: 1
C27: Nota Taller 1 20% | D27: =SUM(D22:D26)+1 -> 7 | E27: =SUM(E23:E26)+1 -> 1
C28: Taller 2. Análisis Cualitativo del Risgo del Proyecto (Riesgo Inherente en matriz de riesgos del Proyecto Taller Integral)
C29: Diseñar y adaptar las escalas de valoración de probabilidad e impacto, en base a la industria de cada proyecto | D29: 2
C30: Utilizar el modelo de 5X5 que mejor se ajuste a la realidad de su proyecto y en función de las escalas determinadas. Hago todos los supuestos que le dicte el "Sentido Común" (EMCDLS) | D30: 2
C31: En base a las escalas anteriores, construir en la Matriz de Riesgos la zona de "Riesgo Inherente" considerando la probabilidad de ocurrencia de cada causa, la categorización y el color respectivo para cada combinación de probabilidad e impacto | D31: 1
C32: Elaborar el Mapa de Riesgos Inherente | D32: 1
C33: Nota Taller 2. 20% | D33: =SUM(D29:D32)+1 -> 7 | E33: =SUM(E29:E32)+1 -> 1
C34: Taller 3 Aplicación del Valor Esperado (Análisis Cualitativo-PERT)
C35: Determinar el riesgo de tiempo y riesgo de costo del proyecto. (Requiere definir y graficar Ruta Crítica) | D35: 1.5
C36: De acuerdo a la tabla de Impacto o Consecuencia (PMI), ¿Cuál es la magnitud del RT y RC)? | D36: 1
C37: Determinar el Fondo de Contingencia y su porcentaje respecto al CBE | D37: 1
C38: Considere los riesgos de tiempo de las tareas no críticas. ¿Qué tareas y rutas de la malla debieran ser monitoreadas cuidadosamente por significar los riesgos más altos? | D38: 1
C39: ¿Cuáles son el costo de completación (CCE) y tiempo de compeltación (TCE) estimados del proyecto? | D39: 1.5
C40: Nota Taller 3. 20% | D40: =SUM(D35:D39)+1 -> 7 | E40: =SUM(E35:E39)+1 -> 1
C41: Taller 4. Estrategia de Respuesta al Riesgo (Plan de Contingencia y Riesgo en Matriz de Riesgos de Proyecto Taller Integral)
C42: Diseñar el plan de Mitigación o Tratamiento al Riesgo, utilizando la Matriz de Riesgos . Al menos 7 riesgos deberán tener tratamiento explícito (no aceptables) | D42: 1.5
C43: Utilizar el modelo 5X5 que mejor se ajuste a la realidad de su proyecto y en función de las escalas determinadas. Haga todos los supuestos que le dicte el sentido común. | D43: 1
C44: Construir la Matriz de Riesgos de la zona de "Riesgo Residual". | D44: 1
C45: Constuir el Mapa de Riesgo Residual con análisis crítico de resultados obtenidos. | D45: 1
C46: Definir el Costo de los Mecanismos de Respuesta y del Fondo de Contingencia. | D46: 1.5
C47: Nota Taller 4. 40% | D47: =SUM(D42:D46)+1 -> 7 | E47: =SUM(E42:E46)+1 -> 1
C48: NOTA FINAL | E48: =+E27*0.2+E33*0.2+E40*0.2+E47*0.4 -> 1
...

Sheet T1-T2-T4 Matriz Riesgos 
B2: Matriz de Riesgos del Proyecto
W3: Monto (en moneda Proyecto) | Y3: %
A4: Proyecto: | F4: Responsable del Proceso: | R4: CAPEX BASE ESTIMADO (CBE): | U4: Costo inevitable de Mitigación al Riesgo | W4: =+T59 -> 0 | Y4: =+W4/T4 -> #DIV/0! | Z4: Costo inevitable
A5: ID del Proyecto | F5: Fecha actualización: | R5: Clase estimación (AACEI) | S5: Clase 1 | U5: Monto del Fondo de Contingencia (evitable) | W5: =+V59 -> 0 | Y5: =+W5/T4 -> #DIV/0! | Z5: Costo evitable
A6: Responsable de emisión: | F6: Revisión N°: | R6: Moneda del Proyecto | S6: US$ | U6: Monto Total de la Gestiòn del Riesgo | W6: =+W4+W5 -> 0 | Y6: =+W6/T4 -> #DIV/0! | AI6: º
B8: Identificación del Riesgo | G8: E. del Desglose de Riesgo | J8: Riesgo Inherente | P8: Plan de Tratamiento al Riesgo | Y8: Riesgos Residual | AE8: Exposición al Riesgo (Seguimiento y Control)
A9: Nro. | B9: Fase / Actividad del Proyecto (WBS) - LD | C9: Descripción del Evento (en neutro, sin expresar causas o impactos) | D9: Causas | E9: Impactos o Consecuencias | F9: Controles existentes (debe ser verificable su existencia en PEP) | G9: Contexto del Riesgo (Interno o Externo) LD | H9: Tipo de Riesgo (RBS) LD | I9: Influencia del Riesgo LD | J9: Porcentaje de la Probabilidad | K9: Probabilidad de Ocurrencia ( P ) | L9: Impacto ( I ) | M9: Severidad (P x I) | N9: Jerarquía | P9: Acción Nro. | Q9: Estrategia de Respuesta (Genérica) | R9: Control a Realizar (Nueva Medida de Mitigación) | S9: Probabilidad de ocurrencia (1%-99%) RIESGO INHERENTE (Repetir celda J) | T9: Costo de mitigación inevitable/ Costo de Corrección. (Respuesta al Riesgo que corrige presupuesto Base) (Ocurra o no el riesgo) | U9: Costo de mitigación evitable / Costo de Corrección. (Respuesta al Riesgo que se implementa sólo en caso de que ocurra) | V9: Fondo de Contingencia (Provisión ded PO x Impacto o costo de corrección para respuestas condicionadas a ocurrencia de evento) (Resultado de celda SxU) | W9: Responsable | X9: Fecha Próximo Control (o plazo de la acción) | Y9: Porcentaje de la Probabilidad | Z9: Probabilidad de Ocurrencia (P) | AA9: Impacto ( I ) | AB9: Severidad (P x I) | AC9: Clasificación (Colores) | AD9: Prioridad | AE9: Características del Control | AH9: Valor del Control | AI9: Calidad del Control | AJ9: Indicador de Exposición al Riesgo Inherente | AK9: Indicador de Exposición al Riesgo Residual | AL9: Nivel de Exposición al Riesgo Inherente | AM9: Nivel de Exposición al Riesgo Residual (Colores)
N10: Clasificación (Colores) | O10: Prioridad | AE10: Periocidad (PD) | AF10: Oportutnidad (O) | AG10: Automatización (A)
A11: R1a | D11: C1: | E11: I1: | F11: CE1: | K11: =_xlfn.XLOOKUP(J11,'Listas Desplegables (LD)'!$J$8:$J$12,'Listas Desplegables (LD)'!$K$8:$K$12, 0,1) -> 0 | M11: =+K11*L11 -> 0 | N11: =+IF(M11>=20,"IV",IF(OR(AND(M11>=9,M11<=16),AND(L11=5,K11=1)),"III",IF(OR(AND(M11<=9,M11>=6),AND(K11=1,L11=4),AND(K11=4,L11=1),AND(K11=1,L11=3)),"II",IF(OR(M11=2,M11=1,AND(L11=1,K11=3),AND(L11=2,K11=2)),"I"," ")))) | O11: 2 | S11: =+J11 -> 0 | Z11: =_xlfn.XLOOKUP(Y11,'Listas Desplegables (LD)'!$J$8:$J$12,'Listas Desplegables (LD)'!$K$8:$K$12, 0,1) -> 0 | AB11: =Z11*AA11 -> 0 | AC11: =+IF(AB11>=20,"IV",IF(OR(AND(AB11>=9,AB11<=16),AND(AA11=5,Z11=1)),"III",IF(OR(AND(AB11<=9,AB11>=6),AND(Z11=1,AA11=4),AND(Z11=4,AA11=1),AND(Z11=1,AA11=3)),"II",IF(OR(AB11=2,AB11=1,AND(AA11=1,Z11=3),AND(AA11=2,Z11=2)),"I"," "))))
O12: 2
A13: R1b | D13: C2: | E13: I2: | F13: CE2: | K13: =_xlfn.XLOOKUP(J13,'Listas Desplegables (LD)'!$J$8:$J$12,'Listas Desplegables (LD)'!$K$8:$K$12, 0,1) -> 0 | M13: =+K13*L13 -> 0 | N13: =+IF(M13>=20,"IV",IF(OR(AND(M13>=9,M13<=16),AND(L13=5,K13=1)),"III",IF(OR(AND(M13<=9,M13>=6),AND(K13=1,L13=4),AND(K13=4,L13=1),AND(K13=1,L13=3)),"II",IF(OR(M13=2,M13=1,AND(L13=1,K13=3),AND(L13=2,K13=2)),"I"," ")))) | O13: 1 | S13: =+J13 -> 0 | Z13: =_xlfn.XLOOKUP(Y13,'Listas Desplegables (LD)'!$J$8:$J$12,'Listas Desplegables (LD)'!$K$8:$K$12, 0,1) -> 0 | AB13: =Z13*AA13 -> 0 | AC13: =+IF(AB13>=20,"IV",IF(OR(AND(AB13>=9,AB13<=16),AND(AA13=5,Z13=1)),"III",IF(OR(AND(AB13<=9,AB13>=6),AND(Z13=1,AA13=4),AND(Z13=4,AA13=1),AND(Z13=1,AA13=3)),"II",IF(OR(AB13=2,AB13=1,AND(AA13=1,Z13=3),AND(AA13=2,Z13=2)),"I"," "))))
O14: 3
A15: R1c | D15: C3: | E15: I3: | F15: CE3: | K15: =_xlfn.XLOOKUP(J15,'Listas Desplegables (LD)'!$J$8:$J$12,'Listas Desplegables (LD)'!$K$8:$K$12, 0,1) -> 0 | M15: =+K15*L15 -> 0 | N15: =+IF(M15>=20,"IV",IF(OR(AND(M15>=9,M15<=16),AND(L15=5,K15=1)),"III",IF(OR(AND(M15<=9,M15>=6),AND(K15=1,L15=4),AND(K15=4,L15=1),AND(K15=1,L15=3)),"II",IF(OR(M15=2,M15=1,AND(L15=1,K15=3),AND(L15=2,K15=2)),"I"," ")))) | O15: 2 | S15: =+J15 -> 0 | Z15: =_xlfn.XLOOKUP(Y15,'Listas Desplegables (LD)'!$J$8:$J$12,'Listas Desplegables (LD)'!$K$8:$K$12, 0,1) -> 0 | AB15: =Z15*AA15 -> 0 | AC15: =+IF(AB15>=20,"IV",IF(OR(AND(AB15>=9,AB15<=16),AND(AA15=5,Z15=1)),"III",IF(OR(AND(AB15<=9,AB15>=6),AND(Z15=1,AA15=4),AND(Z15=4,AA15=1),AND(Z15=1,AA15=3)),"II",IF(OR(AB15=2,AB15=1,AND(AA15=1,Z15=3),AND(AA15=2,Z15=2)),"I"," "))))
O16: 3
A17: R2a | D17: C1: | E17: I1: | F17: CE1: | K17: =_xlfn.XLOOKUP(J17,'Listas Desplegables (LD)'!$J$8:$J$12,'Listas Desplegables (LD)'!$K$8:$K$12, 0,1) -> 0 | M17: =+K17*L17 -> 0 | N17: =+IF(M17>=20,"IV",IF(OR(AND(M17>=9,M17<=16),AND(L17=5,K17=1)),"III",IF(OR(AND(M17<=9,M17>=6),AND(K17=1,L17=4),AND(K17=4,L17=1),AND(K17=1,L17=3)),"II",IF(OR(M17=2,M17=1,AND(L17=1,K17=3),AND(L17=2,K17=2)),"I"," ")))) | S17: =+J17 -> 0 | Z17: =_xlfn.XLOOKUP(Y17,'Listas Desplegables (LD)'!$J$8:$J$12,'Listas Desplegables (LD)'!$K$8:$K$12, 0,1) -> 0 | AB17: =Z17*AA17 -> 0 | AC17: =+IF(AB17>=20,"IV",IF(OR(AND(AB17>=9,AB17<=16),AND(AA17=5,Z17=1)),"III",IF(OR(AND(AB17<=9,AB17>=6),AND(Z17=1,AA17=4),AND(Z17=4,AA17=1),AND(Z17=1,AA17=3)),"II",IF(OR(AB17=2,AB17=1,AND(AA17=1,Z17=3),AND(AA17=2,Z17=2)),"I"," "))))
A19: R2b | D19: C2: | E19: I2: | F19: CE2: | K19: =_xlfn.XLOOKUP(J19,'Listas Desplegables (LD)'!$J$8:$J$12,'Listas Desplegables (LD)'!$K$8:$K$12, 0,1) -> 0 | M19: =+K19*L19 -> 0 | N19: =+IF(M19>=20,"IV",IF(OR(AND(M19>=9,M19<=16),AND(L19=5,K19=1)),"III",IF(OR(AND(M19<=9,M19>=6),AND(K19=1,L19=4),AND(K19=4,L19=1),AND(K19=1,L19=3)),"II",IF(OR(M19=2,M19=1,AND(L19=1,K19=3),AND(L19=2,K19=2)),"I"," ")))) | O19: 2 | S19: =+J19 -> 0 | Z19: =_xlfn.XLOOKUP(Y19,'Listas Desplegables (LD)'!$J$8:$J$12,'Listas Desplegables (LD)'!$K$8:$K$12, 0,1) -> 0 | AB19: =Z19*AA19 -> 0 | AC19: =+IF(AB19>=20,"IV",IF(OR(AND(AB19>=9,AB19<=16),AND(AA19=5,Z19=1)),"III",IF(OR(AND(AB19<=9,AB19>=6),AND(Z19=1,AA19=4),AND(Z19=4,AA19=1),AND(Z19=1,AA19=3)),"II",IF(OR(AB19=2,AB19=1,AND(AA19=1,Z19=3),AND(AA19=2,Z19=2)),"I"," "))))
O20: 2
A21: R2c | D21: C3: | E21: I3: | F21: CE3: | K21: =_xlfn.XLOOKUP(J21,'Listas Desplegables (LD)'!$J$8:$J$12,'Listas Desplegables (LD)'!$K$8:$K$12, 0,1) -> 0 | M21: =+K21*L21 -> 0 | N21: =+IF(M21>=20,"IV",IF(OR(AND(M21>=9,M21<=16),AND(L21=5,K21=1)),"III",IF(OR(AND(M21<=9,M21>=6),AND(K21=1,L21=4),AND(K21=4,L21=1),AND(K21=1,L21=3)),"II",IF(OR(M21=2,M21=1,AND(L21=1,K21=3),AND(L21=2,K21=2)),"I"," ")))) | O21: 3 | S21: =+J21 -> 0 | Z21: =_xlfn.XLOOKUP(Y21,'Listas Desplegables (LD)'!$J$8:$J$12,'Listas Desplegables (LD)'!$K$8:$K$12, 0,1) -> 0 | AB21: =Z21*AA21 -> 0 | AC21: =+IF(AB21>=20,"IV",IF(OR(AND(AB21>=9,AB21<=16),AND(AA21=5,Z21=1)),"III",IF(OR(AND(AB21<=9,AB21>=6),AND(Z21=1,AA21=4),AND(Z21=4,AA21=1),AND(Z21=1,AA21=3)),"II",IF(OR(AB21=2,AB21=1,AND(AA21=1,Z21=3),AND(AA21=2,Z21=2)),"I"," "))))
O22: 2
A23: R3a | D23: C1: | E23: I1: | F23: CE1: | K23: =_xlfn.XLOOKUP(J23,'Listas Desplegables (LD)'!$J$8:$J$12,'Listas Desplegables (LD)'!$K$8:$K$12, 0,1) -> 0 | M23: =+K23*L23 -> 0 | N23: =+IF(M23>=20,"IV",IF(OR(AND(M23>=9,M23<=16),AND(L23=5,K23=1)),"III",IF(OR(AND(M23<=9,M23>=6),AND(K23=1,L23=4),AND(K23=4,L23=1),AND(K23=1,L23=3)),"II",IF(OR(M23=2,M23=1,AND(L23=1,K23=3),AND(L23=2,K23=2)),"I"," ")))) | O23: 1 | S23: =+J23 -> 0 | Z23: =_xlfn.XLOOKUP(Y23,'Listas Desplegables (LD)'!$J$8:$J$12,'Listas Desplegables (LD)'!$K$8:$K$12, 0,1) -> 0 | AB23: =Z23*AA23 -> 0 | AC23: =+IF(AB23>=20,"IV",IF(OR(AND(AB23>=9,AB23<=16),AND(AA23=5,Z23=1)),"III",IF(OR(AND(AB23<=9,AB23>=6),AND(Z23=1,AA23=4),AND(Z23=4,AA23=1),AND(Z23=1,AA23=3)),"II",IF(OR(AB23=2,AB23=1,AND(AA23=1,Z23=3),AND(AA23=2,Z23=2)),"I"," "))))
A25: R3b | D25: C2: | E25: I2: | F25: CE2: | K25: =_xlfn.XLOOKUP(J25,'Listas Desplegables (LD)'!$J$8:$J$12,'Listas Desplegables (LD)'!$K$8:$K$12, 0,1) -> 0 | M25: =+K25*L25 -> 0 | N25: =+IF(M25>=20,"IV",IF(OR(AND(M25>=9,M25<=16),AND(L25=5,K25=1)),"III",IF(OR(AND(M25<=9,M25>=6),AND(K25=1,L25=4),AND(K25=4,L25=1),AND(K25=1,L25=3)),"II",IF(OR(M25=2,M25=1,AND(L25=1,K25=3),AND(L25=2,K25=2)),"I"," ")))) | O25: 2 | S25: =+J25 -> 0 | Z25: =_xlfn.XLOOKUP(Y25,'Listas Desplegables (LD)'!$J$8:$J$12,'Listas Desplegables (LD)'!$K$8:$K$12, 0,1) -> 0 | AB25: =Z25*AA25 -> 0 | AC25: =+IF(AB25>=20,"IV",IF(OR(AND(AB25>=9,AB25<=16),AND(AA25=5,Z25=1)),"III",IF(OR(AND(AB25<=9,AB25>=6),AND(Z25=1,AA25=4),AND(Z25=4,AA25=1),AND(Z25=1,AA25=3)),"II",IF(OR(AB25=2,AB25=1,AND(AA25=1,Z25=3),AND(AA25=2,Z25=2)),"I"," "))))
A27: R3c | D27: C3: | E27: I3: | F27: CE3: | K27: =_xlfn.XLOOKUP(J27,'Listas Desplegables (LD)'!$J$8:$J$12,'Listas Desplegables (LD)'!$K$8:$K$12, 0,1) -> 0 | M27: =+K27*L27 -> 0 | N27: =+IF(M27>=20,"IV",IF(OR(AND(M27>=9,M27<=16),AND(L27=5,K27=1)),"III",IF(OR(AND(M27<=9,M27>=6),AND(K27=1,L27=4),AND(K27=4,L27=1),AND(K27=1,L27=3)),"II",IF(OR(M27=2,M27=1,AND(L27=1,K27=3),AND(L27=2,K27=2)),"I"," ")))) | S27: =+J27 -> 0 | V27: =+U27*S27 -> 0 | Z27: =_xlfn.XLOOKUP(Y27,'Listas Desplegables (LD)'!$J$8:$J$12,'Listas Desplegables (LD)'!$K$8:$K$12, 0,1) -> 0 | AB27: =Z27*AA27 -> 0 | AC27: =+IF(AB27>=20,"IV",IF(OR(AND(AB27>=9,AB27<=16),AND(AA27=5,Z27=1)),"III",IF(OR(AND(AB27<=9,AB27>=6),AND(Z27=1,AA27=4),AND(Z27=4,AA27=1),AND(Z27=1,AA27=3)),"II",IF(OR(AB27=2,AB27=1,AND(AA27=1,Z27=3),AND(AA27=2,Z27=2)),"I"," "))))
V28: =+U28*S27 -> 0
A29: R4a | D29: C1: | E29: I1: | F29: CE1: | K29: =_xlfn.XLOOKUP(J29,'Listas Desplegables (LD)'!$J$8:$J$12,'Listas Desplegables (LD)'!$K$8:$K$12, 0,1) -> 0 | M29: =+K29*L29 -> 0 | N29: =+IF(M29>=20,"IV",IF(OR(AND(M29>=9,M29<=16),AND(L29=5,K29=1)),"III",IF(OR(AND(M29<=9,M29>=6),AND(K29=1,L29=4),AND(K29=4,L29=1),AND(K29=1,L29=3)),"II",IF(OR(M29=2,M29=1,AND(L29=1,K29=3),AND(L29=2,K29=2)),"I"," ")))) | S29: =+J29 -> 0 | V29: =+U29*S29 -> 0 | Z29: =_xlfn.XLOOKUP(Y29,'Listas Desplegables (LD)'!$J$8:$J$12,'Listas Desplegables (LD)'!$K$8:$K$12, 0,1) -> 0 | AB29: =Z29*AA29 -> 0 | AC29: =+IF(AB29>=20,"IV",IF(OR(AND(AB29>=9,AB29<=16),AND(AA29=5,Z29=1)),"III",IF(OR(AND(AB29<=9,AB29>=6),AND(Z29=1,AA29=4),AND(Z29=4,AA29=1),AND(Z29=1,AA29=3)),"II",IF(OR(AB29=2,AB29=1,AND(AA29=1,Z29=3),AND(AA29=2,Z29=2)),"I"," "))))
V30: =+U30*S29 -> 0
A31: R4b | D31: C2: | E31: I2: | F31: CE2: | K31: =_xlfn.XLOOKUP(J31,'Listas Desplegables (LD)'!$J$8:$J$12,'Listas Desplegables (LD)'!$K$8:$K$12, 0,1) -> 0 | M31: =+K31*L31 -> 0 | N31: =+IF(M31>=20,"IV",IF(OR(AND(M31>=9,M31<=16),AND(L31=5,K31=1)),"III",IF(OR(AND(M31<=9,M31>=6),AND(K31=1,L31=4),AND(K31=4,L31=1),AND(K31=1,L31=3)),"II",IF(OR(M31=2,M31=1,AND(L31=1,K31=3),AND(L31=2,K31=2)),"I"," ")))) | S31: =+J31 -> 0 | V31: =+U31*S31 -> 0 | Z31: =_xlfn.XLOOKUP(Y31,'Listas Desplegables (LD)'!$J$8:$J$12,'Listas Desplegables (LD)'!$K$8:$K$12, 0,1) -> 0 | AB31: =Z31*AA31 -> 0 | AC31: =+IF(AB31>=20,"IV",IF(OR(AND(AB31>=9,AB31<=16),AND(AA31=5,Z31=1)),"III",IF(OR(AND(AB31<=9,AB31>=6),AND(Z31=1,AA31=4),AND(Z31=4,AA31=1),AND(Z31=1,AA31=3)),"II",IF(OR(AB31=2,AB31=1,AND(AA31=1,Z31=3),AND(AA31=2,Z31=2)),"I"," "))))
V32: =+U32*S31 -> 0
A33: R4c | D33: C3: | E33: I3: | F33: CE3: | K33: =_xlfn.XLOOKUP(J33,'Listas Desplegables (LD)'!$J$8:$J$12,'Listas Desplegables (LD)'!$K$8:$K$12, 0,1) -> 0 | M33: =+K33*L33 -> 0 | N33: =+IF(M33>=20,"IV",IF(OR(AND(M33>=9,M33<=16),AND(L33=5,K33=1)),"III",IF(OR(AND(M33<=9,M33>=6),AND(K33=1,L33=4),AND(K33=4,L33=1),AND(K33=1,L33=3)),"II",IF(OR(M33=2,M33=1,AND(L33=1,K33=3),AND(L33=2,K33=2)),"I"," ")))) | S33: =+J33 -> 0 | V33: =+U33*S33 -> 0 | Z33: =_xlfn.XLOOKUP(Y33,'Listas Desplegables (LD)'!$J$8:$J$12,'Listas Desplegables (LD)'!$K$8:$K$12, 0,1) -> 0 | AB33: =Z33*AA33 -> 0 | AC33: =+IF(AB33>=20,"IV",IF(OR(AND(AB33>=9,AB33<=16),AND(AA33=5,Z33=1)),"III",IF(OR(AND(AB33<=9,AB33>=6),AND(Z33=1,AA33=4),AND(Z33=4,AA33=1),AND(Z33=1,AA33=3)),"II",IF(OR(AB33=2,AB33=1,AND(AA33=1,Z33=3),AND(AA33=2,Z33=2)),"I"," "))))
V34: =+U34*S33 -> 0
A35: R5a | D35: C1: | E35: I1: | F35: CE1: | K35: =_xlfn.XLOOKUP(J35,'Listas Desplegables (LD)'!$J$8:$J$12,'Listas Desplegables (LD)'!$K$8:$K$12, 0,1) -> 0 | M35: =+K35*L35 -> 0 | N35: =+IF(M35>=20,"IV",IF(OR(AND(M35>=9,M35<=16),AND(L35=5,K35=1)),"III",IF(OR(AND(M35<=9,M35>=6),AND(K35=1,L35=4),AND(K35=4,L35=1),AND(K35=1,L35=3)),"II",IF(OR(M35=2,M35=1,AND(L35=1,K35=3),AND(L35=2,K35=2)),"I"," ")))) | S35: =+J35 -> 0 | V35: =+U35*S35 -> 0 | Z35: =_xlfn.XLOOKUP(Y35,'Listas Desplegables (LD)'!$J$8:$J$12,'Listas Desplegables (LD)'!$K$8:$K$12, 0,1) -> 0 | AB35: =Z35*AA35 -> 0 | AC35: =+IF(AB35>=20,"IV",IF(OR(AND(AB35>=9,AB35<=16),AND(AA35=5,Z35=1)),"III",IF(OR(AND(AB35<=9,AB35>=6),AND(Z35=1,AA35=4),AND(Z35=4,AA35=1),AND(Z35=1,AA35=3)),"II",IF(OR(AB35=2,AB35=1,AND(AA35=1,Z35=3),AND(AA35=2,Z35=2)),"I"," "))))
V36: =+U36*S35 -> 0
A37: R5b | D37: C2: | E37: I2: | F37: CE2: | K37: =_xlfn.XLOOKUP(J37,'Listas Desplegables (LD)'!$J$8:$J$12,'Listas Desplegables (LD)'!$K$8:$K$12, 0,1) -> 0 | M37: =+K37*L37 -> 0 | N37: =+IF(M37>=20,"IV",IF(OR(AND(M37>=9,M37<=16),AND(L37=5,K37=1)),"III",IF(OR(AND(M37<=9,M37>=6),AND(K37=1,L37=4),AND(K37=4,L37=1),AND(K37=1,L37=3)),"II",IF(OR(M37=2,M37=1,AND(L37=1,K37=3),AND(L37=2,K37=2)),"I"," ")))) | S37: =+J37 -> 0 | V37: =+U37*S37 -> 0 | Z37: =_xlfn.XLOOKUP(Y37,'Listas Desplegables (LD)'!$J$8:$J$12,'Listas Desplegables (LD)'!$K$8:$K$12, 0,1) -> 0 | AB37: =Z37*AA37 -> 0 | AC37: =+IF(AB37>=20,"IV",IF(OR(AND(AB37>=9,AB37<=16),AND(AA37=5,Z37=1)),"III",IF(OR(AND(AB37<=9,AB37>=6),AND(Z37=1,AA37=4),AND(Z37=4,AA37=1),AND(Z37=1,AA37=3)),"II",IF(OR(AB37=2,AB37=1,AND(AA37=1,Z37=3),AND(AA37=2,Z37=2)),"I"," "))))
V38: =+U38*S37 -> 0
A39: R5c | D39: C3: | E39: I3: | F39: CE3: | K39: =_xlfn.XLOOKUP(J39,'Listas Desplegables (LD)'!$J$8:$J$12,'Listas Desplegables (LD)'!$K$8:$K$12, 0,1) -> 0 | M39: =+K39*L39 -> 0 | N39: =+IF(M39>=20,"IV",IF(OR(AND(M39>=9,M39<=16),AND(L39=5,K39=1)),"III",IF(OR(AND(M39<=9,M39>=6),AND(K39=1,L39=4),AND(K39=4,L39=1),AND(K39=1,L39=3)),"II",IF(OR(M39=2,M39=1,AND(L39=1,K39=3),AND(L39=2,K39=2)),"I"," ")))) | S39: =+J39 -> 0 | V39: =+U39*S39 -> 0 | Z39: =_xlfn.XLOOKUP(Y39,'Listas Desplegables (LD)'!$J$8:$J$12,'Listas Desplegables (LD)'!$K$8:$K$12, 0,1) -> 0 | AB39: =Z39*AA39 -> 0 | AC39: =+IF(AB39>=20,"IV",IF(OR(AND(AB39>=9,AB39<=16),AND(AA39=5,Z39=1)),"III",IF(OR(AND(AB39<=9,AB39>=6),AND(Z39=1,AA39=4),AND(Z39=4,AA39=1),AND(Z39=1,AA39=3)),"II",IF(OR(AB39=2,AB39=1,AND(AA39=1,Z39=3),AND(AA39=2,Z39=2)),"I"," "))))
V40: =+U40*S39 -> 0
A41: R6a | D41: C1: | E41: I1: | F41: CE1: | K41: =_xlfn.XLOOKUP(J41,'Listas Desplegables (LD)'!$J$8:$J$12,'Listas Desplegables (LD)'!$K$8:$K$12, 0,1) -> 0 | M41: =+K41*L41 -> 0 | N41: =+IF(M41>=20,"IV",IF(OR(AND(M41>=9,M41<=16),AND(L41=5,K41=1)),"III",IF(OR(AND(M41<=9,M41>=6),AND(K41=1,L41=4),AND(K41=4,L41=1),AND(K41=1,L41=3)),"II",IF(OR(M41=2,M41=1,AND(L41=1,K41=3),AND(L41=2,K41=2)),"I"," ")))) | S41: =+J41 -> 0 | V41: =+U41*S41 -> 0 | Z41: =_xlfn.XLOOKUP(Y41,'Listas Desplegables (LD)'!$J$8:$J$12,'Listas Desplegables (LD)'!$K$8:$K$12, 0,1) -> 0 | AB41: =Z41*AA41 -> 0 | AC41: =+IF(AB41>=20,"IV",IF(OR(AND(AB41>=9,AB41<=16),AND(AA41=5,Z41=1)),"III",IF(OR(AND(AB41<=9,AB41>=6),AND(Z41=1,AA41=4),AND(Z41=4,AA41=1),AND(Z41=1,AA41=3)),"II",IF(OR(AB41=2,AB41=1,AND(AA41=1,Z41=3),AND(AA41=2,Z41=2)),"I"," "))))
V42: =+U42*S41 -> 0
A43: R6b | D43: C2: | E43: I2: | F43: CE2: | K43: =_xlfn.XLOOKUP(J43,'Listas Desplegables (LD)'!$J$8:$J$12,'Listas Desplegables (LD)'!$K$8:$K$12, 0,1) -> 0 | M43: =+K43*L43 -> 0 | N43: =+IF(M43>=20,"IV",IF(OR(AND(M43>=9,M43<=16),AND(L43=5,K43=1)),"III",IF(OR(AND(M43<=9,M43>=6),AND(K43=1,L43=4),AND(K43=4,L43=1),AND(K43=1,L43=3)),"II",IF(OR(M43=2,M43=1,AND(L43=1,K43=3),AND(L43=2,K43=2)),"I"," ")))) | S43: =+J43 -> 0 | V43: =+U43*S43 -> 0 | Z43: =_xlfn.XLOOKUP(Y43,'Listas Desplegables (LD)'!$J$8:$J$12,'Listas Desplegables (LD)'!$K$8:$K$12, 0,1) -> 0 | AB43: =Z43*AA43 -> 0 | AC43: =+IF(AB43>=20,"IV",IF(OR(AND(AB43>=9,AB43<=16),AND(AA43=5,Z43=1)),"III",IF(OR(AND(AB43<=9,AB43>=6),AND(Z43=1,AA43=4),AND(Z43=4,AA43=1),AND(Z43=1,AA43=3)),"II",IF(OR(AB43=2,AB43=1,AND(AA43=1,Z43=3),AND(AA43=2,Z43=2)),"I"," "))))
V44: =+U44*S43 -> 0
A45: R6c | D45: C3: | E45: I3: | F45: CE3: | K45: =_xlfn.XLOOKUP(J45,'Listas Desplegables (LD)'!$J$8:$J$12,'Listas Desplegables (LD)'!$K$8:$K$12, 0,1) -> 0 | M45: =+K45*L45 -> 0 | N45: =+IF(M45>=20,"IV",IF(OR(AND(M45>=9,M45<=16),AND(L45=5,K45=1)),"III",IF(OR(AND(M45<=9,M45>=6),AND(K45=1,L45=4),AND(K45=4,L45=1),AND(K45=1,L45=3)),"II",IF(OR(M45=2,M45=1,AND(L45=1,K45=3),AND(L45=2,K45=2)),"I"," ")))) | S45: =+J45 -> 0 | V45: =+U45*S45 -> 0 | Z45: =_xlfn.XLOOKUP(Y45,'Listas Desplegables (LD)'!$J$8:$J$12,'Listas Desplegables (LD)'!$K$8:$K$12, 0,1) -> 0 | AB45: =Z45*AA45 -> 0 | AC45: =+IF(AB45>=20,"IV",IF(OR(AND(AB45>=9,AB45<=16),AND(AA45=5,Z45=1)),"III",IF(OR(AND(AB45<=9,AB45>=6),AND(Z45=1,AA45=4),AND(Z45=4,AA45=1),AND(Z45=1,AA45=3)),"II",IF(OR(AB45=2,AB45=1,AND(AA45=1,Z45=3),AND(AA45=2,Z45=2)),"I"," "))))
...

Sheet T1 RBS (adaptar)
B2: RBS Propuesta por PMI en PMBOK 7 (ver gráfico 11-4)
B4: Nivel 0 RBS | C4: Nivel 1 RBS | D4: Nivel 2 RBS
B5: 0. Tipos de Riesgos desde distintas fuentes | C5: 1. Riesgos Técnicos | D5: 1.1 Definición de Alcance
D6: 1.2 Definición de requisitos
D7: 1.3 Estimaciones, supuestos y restricciones
D8: 1.4 Procesos Técnicos
D9: 1.5 Tecnología
D10: 1.6 Interfases técnicas
D11: 1.7 Otros riesgos técnicos
C12: 2. Riesgos de Gestión | D12: 2.1 Dirección de proyectos
D13: 2.2 Dirección de Programa/Portafolio
D14: 2.3 Gestión de Operaciones
D15: 2.4 Organización
D16: 2.5 Dotación de Recursos
D17: 2.6 Comunicaciones
D18: 2.7 Otros riesgos de gestión
C19: 3. Riesgos Comerciales | D19: 3.1 Términos y condiciones contractuales
D20: 3.2 Contratación interna
D21: 3.3 Proveedores y vendedores
D22: 3.4 Subcontratos
D23: 3.5 Estabilidad de los clientes
D24: 3.6 Asociaciones y empresas conjuntas
D25: 3.7 Otros riesgos comerciales
C26: 4. Riesgos Externos | D26: 4.1 Legislación
D27: 4.2 Tasa de cambio
D28: 4.3 Sustentabilidad y comunidades
D29: 4.4 Ambiental y Clima
D30: 4.5 Competencia
D31: 4.6 Normativo y regulatorio
D32: 4.7 Otros riesgos externos

Sheet Listas Desplegables (LD)
B2: Criterios para elaboración de Listas Desplegables en Matriz de Riesgos (Debe revisarse y adaptarse)
B4: Columna B
B5: WBS del proyecto (Ejemplo a adaptar para cada proyecto) - copiada directamente de MS Project | D5: Columna G | E5: Columna H | F5: Columna I | G5: Columna K | H5: Columna L | I5: Columna Q
B7: Código EDT | C7: Nombre de tarea | D7: Contexto del Riesgo (Interno o Externo) LD | E7: Tipo de Riesgo (RBS) LD | F7: Influencia del Riesgo LD | G7: PO del Riesgo | H7: Impacto Riesgo | I7: Estrategia de Respuesta (Genérica) | J7: Probabilidad Indicativa (límite superior rango) | K7: Puntaje Matriz 5x5
B8: DNA-CAP. | C8: DNA-CAP.Proyecto Habilitación Salas Capacitación DNA 2021 | G8: 1 | H8: 1 | I8: Transferir/compartir | J8: 0.02 | K8: 1
B9: DNA-CAP.LAB | C9: DNA-CAP.LAB Fase 1 Montaje de Laboratorios | D9: Contexto Interno | E9: Considerar listado directamente desde Hoja de Cálculo con RBS | F9: Amenaza | G9: 2 | H9: 2 | I9: Mitigar Probabilidad | J9: 0.1 | K9: 2
B10: DNA-CAP.LAB.1 | C10: DNA-CAP.LAB.1 Trabajos Obras Civiles y modificaciones | D10: Contexto Externo | F10: Oportunidad | G10: 3 | H10: 3 | I10: Mitigar Impacto | J10: 0.5 | K10: 3
B11: DNA-CAP.LAB.2 | C11: DNA-CAP.LAB.2 Instalaciones de Electricidad | G11: 4 | H11: 4 | I11: Aceptar | J11: 0.8 | K11: 4
B12: DNA-CAP.LAB.3 | C12: DNA-CAP.LAB.3 Montaje de la red | G12: 5 | H12: 5 | I12: Eliminar | J12: 0.9999 | K12: 5
B13: DNA-CAP.LAB.3.1 | C13: DNA-CAP.LAB.3.1 Instalar canaletas | I13: Postergar
B14: DNA-CAP.LAB.3.2 | C14: DNA-CAP.LAB.3.2 Instalar cables | I14: Escalar
B15: DNA-CAP.LAB.3.3 | C15: DNA-CAP.LAB.3.3 Instalar tomas de red
B16: DNA-CAP.LAB.3.4 | C16: DNA-CAP.LAB.3.4 Realización de Pruebas de Red
B17: DNA-CAP.LAB.4 | C17: DNA-CAP.LAB.4 Montaje de mobiliario
B18: DNA-CAP.LAB.4.1 | C18: DNA-CAP.LAB.4.1 Montaje de puestos interactivos
B19: DNA-CAP.LAB.4.2 | C19: DNA-CAP.LAB.4.2 Montaje de puestos profesor
B20: DNA-CAP.LAB.4.3 | C20: DNA-CAP.LAB.4.3 Fin de Obras Laboratorios
B21: DNA-CAP.LAB.5 | C21: DNA-CAP.LAB.5 Instalación Equipos Informáticos
B22: DNA-CAP.LAB.5.1 | C22: DNA-CAP.LAB.5.1 Montaje servidores
B23: DNA-CAP.LAB.5.2 | C23: DNA-CAP.LAB.5.2 Montajes PC´s interactivos
B24: DNA-CAP.LAB.5.3 | C24: DNA-CAP.LAB.5.3 Montaje equipamiento videoconferencia
B25: DNA-CAP.LAB.5.4 | C25: DNA-CAP.LAB.5.4 Montaje Proyector Data Show
B26: DNA-CAP.LAB.5.5 | C26: DNA-CAP.LAB.5.5 Fin de Instalación Laboratorios
... B36: DNA-CAP.AP | C36: DNA-CAP.AP Administración del Proyecto
C37: Riesgo Transversal

Sheet T2 Escalas PO
B2: Escala de Probabilidad de Ocurrencia (debe revisarse y adpatarse a industria o proyecto)
B4: Clasificación | C4: Valor Matriz 5x5 | D4: Descripción de la Probabilidad y Frecuencia Indicativa | E4: Probabilidad Indicativa
B5: Casi Seguro | C5: 5 | D5: Prácticamente seguro: muy alta probabilidad de que ocurra, varias veces durante el año. Ha ocurrido en diversas ocasiones en proyectos de similar naturaleza en esta ubicación. | E5: > 0,80
B6: Probable | C6: 4 | D6: Probable: Alta probabilidad, es posible que ocurra una vez al año, aproximadamente. Un evento similar tuvo lugar en diversas oportunidades durante el año, en proyectos de similar índole, para esta organización. | E6: 0,51 - 0,80
B7: Posible | C7: 3 | D7: Posible: probabilidad razonable de que pueda ocurrir por lo menos una vez en un período de 1 a 10 años. Un evento similar tuvo lugar una vez en otros proyectos similares, para esta organización. | E7: 0,11 - 0,50
B8: Improbable | C8: 2 | D8: Improbable: Admisible, es improbable que ocurra durante el proyecto, aunque podría ocurrir durante los próximos 10 a 40 años. Un evento similar ocurrió en otros proyectos similares en esta industria. | E8: 0,02 - 0,10
B9: Raro | C9: 1 | D9: Raro o Infrecuente: muy baja probabilidad de que ocurra, aunque no imposible, es improbable que se produzca durante los próximos 40 años. Un evento similar ocurrió en otro lugar del mundo en esta industria. | E9: < 0,02
B11: Nota: la escala señalada más arriba puede personalizarse, según se requiera, a fin de adecuarse al análisis y período de exposición escogido para el análisis. En la mayoría de los proyectos de gran envergadura, se escoge un período de exposición de 10 años, puesto que, en general, cualquier impacto sobre el costo del proyecto o flujos de caja afectará el VAN dentro de este período de tiempo.

Sheet T2 Escalas Impacto
B2: Escala de Medidión de Impacto o Consecuencia (debe revisarse y adpatarse a industria o proyecto y según definiciones del sponsor)
B4: Clasificación | C4: Valor Matriz 5x5 | D4: Desempeño Técnico Entregables | E4: Presupuesto Proyecto | F4: Cronograma Proyecto | G4: Seguridad y Salud Ocupacional (SSO) | H4: Medio ambiente | I4: Legales y regulaciones | J4: Reputación
B5: Catastrófico | C5: 5 | D5: •No se lograría el 60% de capacidad de diseño de entregables en eatpa de operaciones | E5: •Más del 30% de exceso de gastos | F5: •Más del 50% de atraso en el término del proyecto | G5: •Fatalidades múltiples | H5: •Daño a medio ambiente a largo plazo, 5 años o más, con exigencia > US$5,0MM para compensar, estudios y/o penas. | I5: •Multas y juicios muy importantes | J5: •Desfavorable cobertura de los medios mundiales
J6: •Investigación del Gobierno
D7: •Aumentaría Costos Operacionales (OPEX) > 30% del estimado | I7: •Múltiples litigios | J7: •Gran interés público
J8: •Gran pérdida de apoyo de accionistas
B9: Grave | C9: 4 | D9: •No se lograría 80% capacidad diseño (>60%) sin incurrir en importantes inversiones (CAPEX) (>10% LBC) | E9: •16% a 30% de exceso de gastos | F9: •17% a 50% de atraso en el término del proyecto | G9: •Fatalidad | H9: •Daño a medio ambiente a mediano plazo >1 año < 5 años, con exigencia de US$1,0MM a US$5,0MM para compensar, estudios y/o penas. | I9: •Multas y juicios importantes | J9: •Desfavorable cobertura de los medios nacionales
J10: •Participación de algún miembro del Gobierno
D11: •Aumentaría Costos Operacionales (OPEX) >20% y <30% del estimado | G11: •Lesión vinculada a una invalidez permanente | I11: •Litigios muy graves, incluyendo la acción popular | J11: •Cambio en Gerencia Senior
J12: •Pérdida importante de apoyo de accionistas
B13: Importante | C13: 3 | D13: •No se lograría 100% capacidad diseño sin incurrir en importantes inversiones (CAPEX) (>10% LBC) | E13: •6% a 16% de exceso de gastos | F13: •8% a 17% de atraso en el término del proyecto | G13: •Lesiones graves | H13: •Daño a medio ambiente a corto plazo < 1 año, con exigencia de hasta US$1,0MM para compensar, estudios y/o penas. | I13: •Grave violación de la regulación con investigación o informe a autoridades con posibles juicios y/o multas moderadas. | J13: •Desfavorable cobertura de los medios locales y RRSS
J14: •Participación del Directorio
D15: •Aumentaría Costos Operacionales (OPEX) >10% y <20% del estimado | G15: •Largo tiempo perdido | I15: •Litigios grave, sin acción popular | J15: •Pérdida de apoyo de accionistas
B16: Moderado | C16: 2 | D16: •No se lograría 100% capacidad diseño sin incurrir en inversiones menores (CAPEX) (>5 y <10%% LBC) | E16: •0,5% a 6% de exceso de gastos | F16: •3% a 8% de atraso en el término del proyecto | G16: •Lesiones importante | H16: •Daño medio ambiente con exigencia de hasta US$0,25MM para compensar, estudios y/o penas. | I16: •Violación menor de la regulación con investigación o informe a autoridades con multas moderadas. | J16: •Desfavorable cobertura de los medios locales
J17: •Informe al Directorio
D18: •Aumentaría Costos Operacionales (OPEX) >2% y <10% del estimado | G18: •Tiempo perdido reducido | J18: •Preocupación de accionistas
B20: Menor | C20: 1 | D20: •Se lograría 100% capacidad diseño, pero incurriendo en inversiones menores (CAPEX) (<2% LBC) | E20: •menos de 0,5% de exceso de gastos, dentro de presupuesto | F20: •menos 3% de atraso en el término del proyecto | G20: •Lesiones menores o cuasiaccidentes | H20: •Insignificante impacto ambiental, manejado dentro de presupuesto | I20: •Asunto de bajo nivel legal o de autorización. | J20: •Sin atención de los medios
J21: •Problema planteado por los trabajadores.
B24: Nota: la escala señalada más arriba debe adapatarse a la tolerancia al riesgo de los principales interesados del proyecto.

Sheet T2-T4 Mapas Riesgo (Auto)
K1: 5 | L1: 5 | M1: No tocar estas celdas
B2: Tabla Resumen de Matriz de Riesgos Inherentes | F2: Tabla Resumen de Matriz de Riesgos Residual
B3: Evento | C3: Probabilidad | D3: Impacto | F3: Evento | G3: Probabilidad | H3: Impacto
B4: =+'T1-T2-T4 Matriz Riesgos '!A11 -> R1a | C4: =+'T1-T2-T4 Matriz Riesgos '!K11 -> 0 | D4: =+'T1-T2-T4 Matriz Riesgos '!L11 -> 0 | F4: =+B4 -> R1a | G4: =+'T1-T2-T4 Matriz Riesgos '!Z11 -> 0 | H4: =+'T1-T2-T4 Matriz Riesgos '!AA11 -> 0
B5: =+'T1-T2-T4 Matriz Riesgos '!A13 -> R1b | C5: =+'T1-T2-T4 Matriz Riesgos '!K13 -> 0 | D5: =+'T1-T2-T4 Matriz Riesgos '!L13 -> 0 | F5: =+B5 -> R1b | G5: =+'T1-T2-T4 Matriz Riesgos '!Z13 -> 0 | H5: =+'T1-T2-T4 Matriz Riesgos '!AA13 -> 0
B6: =+'T1-T2-T4 Matriz Riesgos '!A15 -> R1c | C6: =+'T1-T2-T4 Matriz Riesgos '!K15 -> 0 | D6: =+'T1-T2-T4 Matriz Riesgos '!L15 -> 0 | F6: =+B6 -> R1c | G6: =+'T1-T2-T4 Matriz Riesgos '!Z15 -> 0 | H6: =+'T1-T2-T4 Matriz Riesgos '!AA15 -> 0
B7: =+'T1-T2-T4 Matriz Riesgos '!A17 -> R2a | C7: =+'T1-T2-T4 Matriz Riesgos '!K17 -> 0 | D7: =+'T1-T2-T4 Matriz Riesgos '!L17 -> 0 | F7: =+B7 -> R2a | G7: =+'T1-T2-T4 Matriz Riesgos '!Z17 -> 0 | H7: =+'T1-T2-T4 Matriz Riesgos '!AA17 -> 0
B8: =+'T1-T2-T4 Matriz Riesgos '!A19 -> R2b | C8: =+'T1-T2-T4 Matriz Riesgos '!K19 -> 0 | D8: =+'T1-T2-T4 Matriz Riesgos '!L19 -> 0 | F8: =+B8 -> R2b | G8: =+'T1-T2-T4 Matriz Riesgos '!Z19 -> 0 | H8: =+'T1-T2-T4 Matriz Riesgos '!AA19 -> 0
B9: =+'T1-T2-T4 Matriz Riesgos '!A21 -> R2c | C9: =+'T1-T2-T4 Matriz Riesgos '!K21 -> 0 | D9: =+'T1-T2-T4 Matriz Riesgos '!L21 -> 0 | F9: =+B9 -> R2c | G9: =+'T1-T2-T4 Matriz Riesgos '!Z21 -> 0 | H9: =+'T1-T2-T4 Matriz Riesgos '!AA21 -> 0
B10: =+'T1-T2-T4 Matriz Riesgos '!A23 -> R3a | C10: =+'T1-T2-T4 Matriz Riesgos '!K23 -> 0 | D10: =+'T1-T2-T4 Matriz Riesgos '!L23 -> 0 | F10: =+B10 -> R3a | G10: =+'T1-T2-T4 Matriz Riesgos '!Z23 -> 0 | H10: =+'T1-T2-T4 Matriz Riesgos '!AA23 -> 0
B11: =+'T1-T2-T4 Matriz Riesgos '!A25 -> R3b | C11: =+'T1-T2-T4 Matriz Riesgos '!K25 -> 0 | D11: =+'T1-T2-T4 Matriz Riesgos '!L25 -> 0 | F11: =+B11 -> R3b | G11: =+'T1-T2-T4 Matriz Riesgos '!Z25 -> 0 | H11: =+'T1-T2-T4 Matriz Riesgos '!AA25 -> 0
B12: =+'T1-T2-T4 Matriz Riesgos '!A27 -> R3c | C12: =+'T1-T2-T4 Matriz Riesgos '!K27 -> 0 | D12: =+'T1-T2-T4 Matriz Riesgos '!L27 -> 0 | F12: =+B12 -> R3c | G12: =+'T1-T2-T4 Matriz Riesgos '!Z27 -> 0 | H12: =+'T1-T2-T4 Matriz Riesgos '!AA27 -> 0
B13: =+'T1-T2-T4 Matriz Riesgos '!A29 -> R4a | C13: =+'T1-T2-T4 Matriz Riesgos '!K29 -> 0 | D13: =+'T1-T2-T4 Matriz Riesgos '!L29 -> 0 | F13: =+B13 -> R4a | G13: =+'T1-T2-T4 Matriz Riesgos '!Z29 -> 0 | H13: =+'T1-T2-T4 Matriz Riesgos '!AA29 -> 0
B14: =+'T1-T2-T4 Matriz Riesgos '!A31 -> R4b | C14: =+'T1-T2-T4 Matriz Riesgos '!K31 -> 0 | D14: =+'T1-T2-T4 Matriz Riesgos '!L31 -> 0 | F14: =+B14 -> R4b | G14: =+'T1-T2-T4 Matriz Riesgos '!Z31 -> 0 | H14: =+'T1-T2-T4 Matriz Riesgos '!AA31 -> 0
B15: =+'T1-T2-T4 Matriz Riesgos '!A33 -> R4c | C15: =+'T1-T2-T4 Matriz Riesgos '!K33 -> 0 | D15: =+'T1-T2-T4 Matriz Riesgos '!L33 -> 0 | F15: =+B15 -> R4c | G15: =+'T1-T2-T4 Matriz Riesgos '!Z33 -> 0 | H15: =+'T1-T2-T4 Matriz Riesgos '!AA33 -> 0
B16: =+'T1-T2-T4 Matriz Riesgos '!A35 -> R5a | C16: =+'T1-T2-T4 Matriz Riesgos '!K35 -> 0 | D16: =+'T1-T2-T4 Matriz Riesgos '!L35 -> 0 | F16: =+B16 -> R5a | G16: =+'T1-T2-T4 Matriz Riesgos '!Z35 -> 0 | H16: =+'T1-T2-T4 Matriz Riesgos '!AA35 -> 0
B17: =+'T1-T2-T4 Matriz Riesgos '!A37 -> R5b | C17: =+'T1-T2-T4 Matriz Riesgos '!K37 -> 0 | D17: =+'T1-T2-T4 Matriz Riesgos '!L37 -> 0 | F17: =+B17 -> R5b | G17: =+'T1-T2-T4 Matriz Riesgos '!Z37 -> 0 | H17: =+'T1-T2-T4 Matriz Riesgos '!AA37 -> 0
B18: =+'T1-T2-T4 Matriz Riesgos '!A39 -> R5c | C18: =+'T1-T2-T4 Matriz Riesgos '!K39 -> 0 | D18: =+'T1-T2-T4 Matriz Riesgos '!L39 -> 0 | F18: =+B18 -> R5c | G18: =+'T1-T2-T4 Matriz Riesgos '!Z39 -> 0 | H18: =+'T1-T2-T4 Matriz Riesgos '!AA39 -> 0
B19: =+'T1-T2-T4 Matriz Riesgos '!A41 -> R6a | C19: =+'T1-T2-T4 Matriz Riesgos '!K41 -> 0 | D19: =+'T1-T2-T4 Matriz Riesgos '!L41 -> 0 | F19: =+B19 -> R6a | G19: =+'T1-T2-T4 Matriz Riesgos '!Z41 -> 0 | H19: =+'T1-T2-T4 Matriz Riesgos '!AA41 -> 0
B20: =+'T1-T2-T4 Matriz Riesgos '!A43 -> R6b | C20: =+'T1-T2-T4 Matriz Riesgos '!K43 -> 0 | D20: =+'T1-T2-T4 Matriz Riesgos '!L43 -> 0 | F20: =+B20 -> R6b | G20: =+'T1-T2-T4 Matriz Riesgos '!Z43 -> 0 | H20: =+'T1-T2-T4 Matriz Riesgos '!AA43 -> 0
B21: =+'T1-T2-T4 Matriz Riesgos '!A45 -> R6c | C21: =+'T1-T2-T4 Matriz Riesgos '!K45 -> 0 | D21: =+'T1-T2-T4 Matriz Riesgos '!L45 -> 0 | F21: =+B21 -> R6c | G21: =+'T1-T2-T4 Matriz Riesgos '!Z45 -> 0 | H21: =+'T1-T2-T4 Matriz Riesgos '!AA45 -> 0
B22: =+'T1-T2-T4 Matriz Riesgos '!A47 -> R7a | C22: =+'T1-T2-T4 Matriz Riesgos '!K47 -> 0 | D22: =+'T1-T2-T4 Matriz Riesgos '!L47 -> 0 | F22: =+B22 -> R7a | G22: =+'T1-T2-T4 Matriz Riesgos '!Z47 -> 0 | H22: =+'T1-T2-T4 Matriz Riesgos '!AA47 -> 0
B23: =+'T1-T2-T4 Matriz Riesgos '!A49 -> R7b | C23: =+'T1-T2-T4 Matriz Riesgos '!K49 -> 0 | D23: =+'T1-T2-T4 Matriz Riesgos '!L49 -> 0 | F23: =+B23 -> R7b | G23: =+'T1-T2-T4 Matriz Riesgos '!Z49 -> 0 | H23: =+'T1-T2-T4 Matriz Riesgos '!AA49 -> 0
B24: =+'T1-T2-T4 Matriz Riesgos '!A51 -> R7c | C24: =+'T1-T2-T4 Matriz Riesgos '!K51 -> 0 | D24: =+'T1-T2-T4 Matriz Riesgos '!L51 -> 0 | F24: =+B24 -> R7c | G24: =+'T1-T2-T4 Matriz Riesgos '!Z51 -> 0 | H24: =+'T1-T2-T4 Matriz Riesgos '!AA51 -> 0
B25: =+'T1-T2-T4 Matriz Riesgos '!A53 -> R8a | C25: =+'T1-T2-T4 Matriz Riesgos '!K53 -> 0 | D25: =+'T1-T2-T4 Matriz Riesgos '!L53 -> 0 | F25: =+B25 -> R8a | G25: =+'T1-T2-T4 Matriz Riesgos '!Z53 -> 0 | H25: =+'T1-T2-T4 Matriz Riesgos '!AA53 -> 0
B26: =+'T1-T2-T4 Matriz Riesgos '!A55 -> R8b | C26: =+'T1-T2-T4 Matriz Riesgos '!K55 -> 0 | D26: =+'T1-T2-T4 Matriz Riesgos '!L55 -> 0 | F26: =+B26 -> R8b | G26: =+'T1-T2-T4 Matriz Riesgos '!Z55 -> 0 | H26: =+'T1-T2-T4 Matriz Riesgos '!AA55 -> 0
B27: =+'T1-T2-T4 Matriz Riesgos '!A57 -> R8c | C27: =+'T1-T2-T4 Matriz Riesgos '!K57 -> 0 | D27: =+'T1-T2-T4 Matriz Riesgos '!L57 -> 0 | F27: =+B27 -> R8c | G27: =+'T1-T2-T4 Matriz Riesgos '!Z57 -> 0 | H27: =+'T1-T2-T4 Matriz Riesgos '!AA57 -> 0

Sheet T2-T4 Mapas (manual)
B2: Mapa de Riesgo Inherente | J2: Mapa de Riesgo Residual
D3: Impacto | L3: Impacto
D4: 1 Menor | E4: 2 Moderado | F4: 3 Importante | G4: 4 Grave | H4: 5 Catastrófico | L4: 1 Menor | M4: 2 Moderado | N4: 3 Importante | O4: 4 Grave | P4: 5 Catastrófico
B5: Probabilidad | C5: 5 Casi seguro | D5: Medio (II) | E5: Alto (III) | F5: Alto (III) | G5: Extremo (IV) | H5: Extremo (IV) | J5: Probabilidad | K5: 5 Casi seguro | L5: Medio (II) | M5: Alto (III) | N5: Alto (III) | O5: Extremo (IV) | P5: Extremo (IV)
C6: 4 Probable | D6: Medio (II) | E6: Medio (II) | F6: Alto (III) | G6: Alto (III) | H6: Extremo (IV) | K6: 4 Probable | L6: Medio (II) | M6: Medio (II) | N6: Alto (III) | O6: Alto (III) | P6: Extremo (IV)
C7: 3 Posible | D7: Bajo (I) | E7: Medio (II) | F7: Alto (III) | G7: Alto (III) | H7: Alto (III) | K7: 3 Posible | L7: Bajo (I) | M7: Medio (II) | N7: Alto (III) | O7: Alto (III) | P7: Alto (III)
C8: 2 Improbable | D8: Bajo (I) | E8: Bajo (I) | F8: Medio (II) | G8: Medio (II) | H8: Alto (III) | K8: 2 Improbable | L8: Bajo (I) | M8: Bajo (I) | N8: Medio (II) | O8: Medio (II) | P8: Alto (III)
C9: 1 Raro | D9: Bajo (I) | E9: Bajo (I) | F9: Medio (II) | G9: Medio (II) | H9: Alto (III) | K9: 1 Raro | L9: Bajo (I) | M9: Bajo (I) | N9: Medio (II) | O9: Medio (II) | P9: Alto (III)

Sheet T3 Modelo Valor Esperado y PERT
B2: Taller N° 3 Aplicación del modelo de valor esperado
B4: Descripción
B5: En la malla siguiente se muestra la secuencia de actividades de un proyecto de mantenimiento de 8 paquetes de trabajo:
F9: TAREA S 3 semanas | H9: TAREA T 5 semanas | J9: TAREA U 7 semanas
D11: TAREA L 9 semanas
B13: INICIO | L13: FIN
F15: TAREA V 8 semanas | H15: TAREA J 3 semanas | J15: TAREA C 6 semanas
H21: TAREA R 4 semanas
B27: La tabla siguiente muestra los valores del costo base (CBE) y estimación de tiempos inicial (TBE), | J27: CCE = CBE + (CC * P)
B28: como también el costo de correción (CC) y tiempo de correción (TC) | G28: estimados y la probabilidad | J28: TCE = TBE + (TC * P)
B29: de ocurrencia (P) del evento riesgo asociado a cada paquete de trabajo del proyecto.
B30: Costos expresados en dólares, tiempo expresado en semanas.
H31: Pregunta 1, 2 y 3 | J31: Pregunta 4 | K31: Pregunta 5
B32: Paquete de trabajo según WBS | C32: Costo base estimado (CBE) | D32: Tiempo Base estimado (TBE) | E32: Costo de corrección (CC) | F32: Tiempo de corrección (TC) | G32: Probabilidad (P) | H32: Riesgo de Costo (RC) | I32: Riesgo de Tiempo (RT) | J32: Tareas no criticas que deben ser monitoreadas | K32: Costo de completación (CCE) | L32: Tiempo de completación (TCE)
B33: L | C33: 21000 | D33: 9 | E33: 3000 | F33: 2 | G33: 0.2
B34: V | C34: 18000 | D34: 8 | E34: 5000 | F34: 3 | G34: 0.3
B35: T | C35: 33000 | D35: 5 | E35: 9000 | F35: 2 | G35: 0.1
B36: U | C36: 22000 | D36: 7 | E36: 10000 | F36: 4 | G36: 0.2
B37: S | C37: 17000 | D37: 3 | E37: 5000 | F37: 1 | G37: 0.3
B38: J | C38: 15000 | D38: 3 | E38: 3000 | F38: 3 | G38: 0.1
B39: R | C39: 10000 | D39: 4 | E39: 4000 | F39: 2 | G39: 0.3
B40: C | C40: 15000 | D40: 6 | E40: 5000 | F40: 5 | G40: 0.3
B41: Totales | C41: =SUM(C33:C40) -> 151000
H43: RIESGO DE COSTO | I43: RIESGO DE TIEMPO
B45: Preguntas: | C45: 1.- Determinar el riesgo de tiempo y riesgo de costo del proyecto
C46: El riesgo de tiempo del proceso crítico es:
C47: El riesgo de costo del proceso crítico es:
C48: 2.- De acuerdo a la tabla de Impacto y Consecuencia vista en clases ¿Cuál es la magnitud del RT y RC?
C49: La Magnitud del RT (Concepto y %)
C50: La Magnitud del RC (Concepto y %)
C51: 3.- Determinar el Fondo de Contingencia y su porcentaje respecto al CBE
C52: El fondo de Contingencia es: | I52: explicar
C53: El porcentaje con respecto al CBE es:
C54: 4.- Considere los riesgos de tiempo de las tareas no críticas. ¿Qué tareas y rutas de la malla deberían ser
C55: monitoreados cuidadosamente por significar los riesgos más altos?
C56: Tareas No críticas a monitorear son:
C58: 5.- ¿Cuáles son el costo de completación (CCE) y tiempo de completación (TCE) estimados del proyecto?
C59: El costo de completación (CCE) es:
C60: El tiempo de completación (TCE) es:
