Workbook
Name Avance: {"MO(BASE)",#N/A,FALSE,"MO(BASE)";"MO(BASE)1",#N/A,FALSE,"MO(BASE)";"MO(BASE)2",#N/A,FALSE,"MO(BASE)"}
Name dh_mes: #REF!
Name dot_agua: #REF!
Name dot_ap: #REF!
Name dot_dist: #REF!
Name dot_mina: #REF!
Name dot_oca: #REF!
Name dot_per: #REF!
Name dotacion: #REF!
Name dotacion_CMDIC: #REF!
Name Dotación_Distribución: #REF!
Name Examenes: #REF!,#REF!,#REF!,#REF!,#REF!,#REF!,#REF!,#REF!,#REF!,#REF!,#REF!,#REF!,#REF!,#REF!,#REF!,#REF!,#REF!,#REF!,#REF!,#REF!,#REF!,#REF!,#REF!,#REF!,#REF!,#REF!,#REF!,#REF!,#REF!
Name hd: #REF!
Name IPC: #REF!
Name IPCB: #REF!
Name MACU: #N/A
Name mes: #REF!
Name NvsASD: "V2002-01-31"
Name NvsAutoDrillOk: "VN"
Name NvsEndTime: 37298.8705142361
Name NvsInstSpec: "%"
Name NvsLayoutType: "M3"
Name NvsNplSpec: "%,X,RZT.ACCOUNT.,CZF.."
Name NvsPanelEffdt: "V1901-01-01"
Name NvsPanelSetid: "VGRALS"
Name NvsReqBU: "VEL011"
Name NvsReqBUOnly: "VY"
Name NvsTransLed: "VN"
Name NvsTreeASD: "V2002-01-31"
Name NvsValTbl.BUSINESS_UNIT: "BUS_UNIT_TBL_GL"
Name pc_agua: #REF!
Name pc_ap: #REF!
Name pc_dist: #REF!
Name pc_mina: #REF!
Name Personal_STN: #REF!,#REF!,#REF!,#REF!,#REF!,#REF!,#REF!,#REF!,#REF!,#REF!,#REF!,#REF!,#REF!,#REF!
Name USD: #REF!
Name VBMEL: #REF!,#REF!,#REF!,#REF!,#REF!,#REF!,#REF!,#REF!,#REF!,#REF!,#REF!,#REF!,#REF!,#REF!,#REF!,#REF!,#REF!,#REF!,#REF!,#REF!,#REF!,#REF!,#REF!,#REF!,#REF!,#REF!,#REF!,#REF!

Sheet Dashboard_Ejecutivo
B2: DASHBOARD EJECUTIVO - CONTROL INTEGRAL DEL PROYECTO
B4: Proyecto: Aumento Capacidad BP1 SE O'Higgins
B5: Fecha de Corte: 26 de Mayo 2026
B8: 1. SALUD FINANCIERA (EVM & CURVA S)
B9: Presupuesto Total (BAC) | C9: =+Resumen_Control_Costos!C14 -> 2.5302808e+08
B10: Costo Real Incurrido (AC) | C10: =+Resumen_Control_Costos!D14 -> 200000
B11: Estimación al Cierre (EAC) | C11: =+Resumen_Control_Costos!F14 -> 2.5302808e+08
B12: Índice Desempeño Costo (CPI) | C12: =+Resumen_Control_Costos!C24 -> 2.4
B13: Índice Desempeño Crono (SPI) | C13: =+Resumen_Control_Costos!C23 -> Pendiente datos
B14: Variación al Término (VAC) | C14: =+Resumen_Control_Costos!C27 -> 199997.6
B16: 2. RECURSOS HUMANOS Y PRODUCTIVIDAD | M16: Recurso | N16: HH Plan | O16: HH Real
B17: Dotación Total (Organigrama) | C17: =COUNTA(RRHH_Control!A2:A19) -> 18 | M17: May | N17: 1500 | O17: 1250
B18: Personal con Examenes Aprobados | C18: =COUNTIFS(RRHH_Control!E:E, "Aprobado", RRHH_Control!F:F, "Aprobado") -> 16 | M18: Jun | N18: 2000 | O18: 0
B19: Personal con Carta Oferta / Anexo | C19: =COUNTIFS(RRHH_Control!S:S, "Aprobado") + COUNTIFS(RRHH_Control!U:U, "Aprobado") -> 15
B20: Personal 100% Acreditado | C20: =COUNTIF(RRHH_Control!AP2:AP99, 3) -> 0
B21: Promedio Avance HDR | C21: =AVERAGE(HDR_Matriz!BI2:BI100) -> 0
B22: Horas Hombre (HH) Consumidas | C22: =SUM(Curva_S_Avance!H22) -> 1250
B23: Riesgos Abiertos | C23: =COUNTIF('Matriz de Riesgos'!I3:I101, "Abierto") -> 0
B24: Avance Carpeta de Arranque STN (N°) | C24: =COUNTIF('Carpeta de Arranque_STN'!L14:L50, 1) -> 1
B25: Avance Carpeta de Arranque STN (%) | C25: =IFERROR(AVERAGE('Carpeta de Arranque_STN'!L14:L50), 0) -> 0.375
B27: 3. CALIDAD (QA/QC) Y COMPROMISOS
B28: Tareas Compromisos Totales | C28: 9
B29: Protocolos QA/QC Generados | C29: 0
B30: Protocolos QA/QC Aprobados MEL | C30: 0
B31: % Liberación QA/QC | C31: =IF(D22>0,D23/D22,0) -> 0
B32: Procedimientos a Generar | C32: Vincular
B33: % Procedimientos Generados | C33: Vincular
B35: 4. EQUIPOS RODANTES Y TOPOGRAFÍA
B36: Total Equipos y Vehículos | C36: =COUNTA(Equipos_y_Flota!A2:A99) -> 8
B37: Equipos 100% Acreditados | C37: =COUNTIF(Equipos_y_Flota!P2:P99, 3) -> 0
B38: Avance Promedio Flota | C38: Vincular
B39: N° de Camionetas | C39: Vincular
B40: % de Avance en Acreditación Camionetas | C40: Vincular
B41: N° Camión Pluma | C41: Vincular
B42: % de Avance en Acreditación Camion | C42: Vincular
B44: 5. DOCUMENTACION CONTRACTUAL
B45: Orden de Servicio STN | C45: OK
B46: Contrato KELTI / STN | C46: NA
B47: Contrato STN creado en PMF | C47: OK
B48: Orden de Servicio CTC Global | C48: OK
...

Sheet Resumen_Control_Costos
B2: CONTROL DE COSTOS Y GESTIÓN DEL VALOR GANADO (EVM)
B5: PRESUPUESTO BASE (BAC) Y FORECAST POR CUENTA
B6: Cuenta / Item | C6: Presupuesto (BAC) | D6: Real a la Fecha (AC) | E6: Comprometido | F6: Estimación a Término (EAC) | G6: Desviación al Cierre (VAC)
B7: RRHH | C7: =+Control_Presupuesto!C2 -> 62700000 | D7: =+Control_Presupuesto!I2 -> 0 | E7: =+Control_Presupuesto!J2 -> 0 | F7: =IFERROR(C7, "Pendiente datos") -> 62700000 | G7: =IFERROR(C7-F7, "Pendiente datos") -> 0
B8: MATERIALES | C8: =+Control_Presupuesto!C12 -> 2956644.4 | D8: =+Control_Presupuesto!I12 -> 0 | E8: =+Control_Presupuesto!J12 -> 0 | F8: =IFERROR(C8, "Pendiente datos") -> 2956644.4 | G8: =IFERROR(C8-F8, "Pendiente datos") -> 0
B9: EQUIPOS MAQUINARIA | C9: =+Control_Presupuesto!C16 -> 57720797 | D9: =+Control_Presupuesto!I16 -> 0 | E9: =+Control_Presupuesto!J16 -> 0 | F9: =IFERROR(C9, "Pendiente datos") -> 57720797 | G9: =IFERROR(C9-F9, "Pendiente datos") -> 0
B10: SUBCONTRATOS | C10: =+Control_Presupuesto!C22 -> 4510650 | D10: =+Control_Presupuesto!I22 -> 0 | E10: =+Control_Presupuesto!J22 -> 0 | F10: =IFERROR(C10, "Pendiente datos") -> 4510650 | G10: =IFERROR(C10-F10, "Pendiente datos") -> 0
B11: CTC GLOBAL | C11: =+Control_Presupuesto!C26 -> 17980000 | D11: =+Control_Presupuesto!I26 -> 0 | E11: =+Control_Presupuesto!J26 -> 0 | F11: =IFERROR(C11, "Pendiente datos") -> 17980000 | G11: =IFERROR(C11-F11, "Pendiente datos") -> 0
B12: GASTOS GENERALES | C12: =+Control_Presupuesto!C30 -> 80209991 | D12: =+Control_Presupuesto!I30 -> 200000 | E12: =+Control_Presupuesto!J30 -> 0 | F12: =IFERROR(C12, "Pendiente datos") -> 80209991 | G12: =IFERROR(C12-F12, "Pendiente datos") -> 0
B13: IMPREVISTOS | C13: =+Control_Presupuesto!C37 -> 26950000 | D13: =+Control_Presupuesto!I37 -> 0 | E13: =+Control_Presupuesto!J37 -> 0 | F13: =IFERROR(C13, "Pendiente datos") -> 26950000 | G13: =IFERROR(C13-F13, "Pendiente datos") -> 0
B14: TOTAL COSTOS | C14: =IFERROR(SUM(C7:C13), "Pendiente datos") -> 2.5302808e+08 | D14: =IFERROR(SUM(D7:D13), "Pendiente datos") -> 200000 | E14: =IFERROR(SUM(E7:E13), "Pendiente datos") -> 0 | F14: =IFERROR(SUM(F7:F13), "Pendiente datos") -> 2.5302808e+08 | G14: =IFERROR(SUM(G7:G13), "Pendiente datos") -> 0
B17: INDICADORES CLAVE DE DESEMPEÑO (KPIs EVM - PMI) - MAYO 2026
B18: Indicador | C18: Valor | D18: Descripción
B19: Valor Planeado (PV) | C19: =IFERROR(253028082 * Curva_S_Avance!C7, "Pendiente datos") -> 30363370 | D19: Presupuesto autorizado asignado al trabajo programado.
B20: Valor Ganado (EV) | C20: =IFERROR(253028082 * Curva_S_Avance!C9, "Pendiente datos") -> 12651404 | D20: Medida del trabajo realizado en términos del presupuesto.
B21: Costo Real (AC) | C21: =IFERROR(D14, "Pendiente datos") -> 200000 | D21: Costo incurrido por el trabajo realizado a la fecha.
B22: Presupuesto (BAC) | C22: =IFERROR(C14, "Pendiente datos") -> 2.5302808e+08 | D22: Presupuesto total al finalizar.
B23: Índice Desempeño Cronograma (SPI) | C23: =IFERROR(C19/C18, "Pendiente datos") -> Pendiente datos | D23: EV / PV (>1 es adelantado, <1 atrasado)
B24: Índice Desempeño Costo (CPI) | C24: =IFERROR(C19/C20, "Pendiente datos") -> 2.4 | D24: EV / AC (>1 es ahorro, <1 sobrecosto)
B25: Estimación a Término (EAC) | C25: =IFERROR(C21/C23, "Pendiente datos") -> Pendiente datos | D25: Costo total estimado al finalizar el proyecto (BAC/CPI).
B26: Estimación para Terminar (ETC) | C26: =IFERROR(C24-C20, "Pendiente datos") -> -12651402 | D26: Costo esperado para terminar el trabajo restante (EAC - AC).
B27: Variación al Término (VAC) | C27: =IFERROR(C21-C24, "Pendiente datos") -> 199997.6 | D27: Déficit o superávit proyectado (BAC - EAC).

Sheet Control_Presupuesto
A1: WBS | B1: Descripción de la Partida | C1: Presupuesto Base (BAC) | D1: Gasto Real Mayo 2026 | E1: Gasto Real Junio 2026 | F1: Gasto Real Julio 2026 | G1: Gasto Real Agosto 2026 | H1: Gasto Real Sept 2026 | I1: Costo Real Acumulado (AC) | J1: Comprometido (OC) | K1: Costo Total Actual | L1: Presupuesto Disponible | M1: Avance Real (%) | N1: Valor Ganado (EV) | O1: Desviación a la fecha (CV) | P1: Estimación p/Terminar (ETC) | Q1: Forecast (EAC) | R1: Desviación Proyectada (VAC) | S1: Comentarios
A2: 1.0 | B2: RRHH DIRECTO E INDIRECTO | C2: =SUM(C3:C11) -> 62700000 | D2: =SUM(D3:D11) -> 0 | E2: =SUM(E3:E11) -> 0 | F2: =SUM(F3:F11) -> 0 | G2: =SUM(G3:G11) -> 0 | H2: =SUM(H3:H11) -> 0 | I2: =SUM(D2:G2) -> 0 | J2: 0 | K2: =I2+J2 -> 0 | L2: =C2-K2 -> 62700000 | M2: 0 | N2: =C2*M2 -> 0 | O2: =N2-I2 -> 0 | P2: 0 | Q2: =K2+P2 -> 0 | R2: =C2-Q2 -> 62700000
A3: 1.1 | B3: Supervisor de Terreno | C3: 6900000 | D3: =SUMIFS(Costos_Extracontables!$D:$D, Costos_Extracontables!$E:$E, $B3, Costos_Extracontables!$C:$C, ">=2026-05-01", Costos_Extracontables!$C:$C, "<=2026-05-31") -> 0 | E3: =SUMIFS(Costos_Extracontables!$D:$D, Costos_Extracontables!$E:$E, $B3, Costos_Extracontables!$C:$C, ">=2026-06-01", Costos_Extracontables!$C:$C, "<=2026-06-31") -> 0 | I3: =SUM(D3:G3) -> 0 | J3: 0 | K3: =I3+J3 -> 0 | L3: =C3-K3 -> 6900000 | M3: 0 | N3: =C3*M3 -> 0 | O3: =N3-I3 -> 0 | P3: 0 | Q3: =K3+P3 -> 0 | R3: =C3-Q3 -> 6900000
A4: 1.2 | B4: Administrativo de Obras y RRLL | C4: 4200000 | D4: =SUMIFS(Costos_Extracontables!$D:$D, Costos_Extracontables!$E:$E, $B4, Costos_Extracontables!$C:$C, ">=2026-05-01", Costos_Extracontables!$C:$C, "<=2026-05-31") -> 0 | E4: =SUMIFS(Costos_Extracontables!$D:$D, Costos_Extracontables!$E:$E, $B4, Costos_Extracontables!$C:$C, ">=2026-06-01", Costos_Extracontables!$C:$C, "<=2026-06-31") -> 0 | I4: =SUM(D4:G4) -> 0 | J4: 0 | K4: =I4+J4 -> 0 | L4: =C4-K4 -> 4200000 | M4: 0 | N4: =C4*M4 -> 0 | O4: =N4-I4 -> 0 | P4: 0 | Q4: =K4+P4 -> 0 | R4: =C4-Q4 -> 4200000
A5: 1.3 | B5: Topógrafo | C5: 5400000 | D5: =SUMIFS(Costos_Extracontables!$D:$D, Costos_Extracontables!$E:$E, $B5, Costos_Extracontables!$C:$C, ">=2026-05-01", Costos_Extracontables!$C:$C, "<=2026-05-31") -> 0 | E5: =SUMIFS(Costos_Extracontables!$D:$D, Costos_Extracontables!$E:$E, $B5, Costos_Extracontables!$C:$C, ">=2026-06-01", Costos_Extracontables!$C:$C, "<=2026-06-31") -> 0 | I5: =SUM(D5:G5) -> 0 | J5: 0 | K5: =I5+J5 -> 0 | L5: =C5-K5 -> 5400000 | M5: 0 | N5: =C5*M5 -> 0 | O5: =N5-I5 -> 0 | P5: 0 | Q5: =K5+P5 -> 0 | R5: =C5-Q5 -> 5400000
A6: 1.4 | B6: Alarife | C6: 3000000 | D6: =SUMIFS(Costos_Extracontables!$D:$D, Costos_Extracontables!$E:$E, $B6, Costos_Extracontables!$C:$C, ">=2026-05-01", Costos_Extracontables!$C:$C, "<=2026-05-31") -> 0 | E6: =SUMIFS(Costos_Extracontables!$D:$D, Costos_Extracontables!$E:$E, $B6, Costos_Extracontables!$C:$C, ">=2026-06-01", Costos_Extracontables!$C:$C, "<=2026-06-31") -> 0 | I6: =SUM(D6:G6) -> 0 | J6: 0 | K6: =I6+J6 -> 0 | L6: =C6-K6 -> 3000000 | M6: 0 | N6: =C6*M6 -> 0 | O6: =N6-I6 -> 0 | P6: 0 | Q6: =K6+P6 -> 0 | R6: =C6-Q6 -> 3000000
A7: 1.5 | B7: Maestro 1° Líneas Senior | C7: 4800000 | D7: =SUMIFS(Costos_Extracontables!$D:$D, Costos_Extracontables!$E:$E, $B7, Costos_Extracontables!$C:$C, ">=2026-05-01", Costos_Extracontables!$C:$C, "<=2026-05-31") -> 0 | E7: =SUMIFS(Costos_Extracontables!$D:$D, Costos_Extracontables!$E:$E, $B7, Costos_Extracontables!$C:$C, ">=2026-06-01", Costos_Extracontables!$C:$C, "<=2026-06-31") -> 0 | I7: =SUM(D7:G7) -> 0 | J7: 0 | K7: =I7+J7 -> 0 | L7: =C7-K7 -> 4800000 | M7: 0 | N7: =C7*M7 -> 0 | O7: =N7-I7 -> 0 | P7: 0 | Q7: =K7+P7 -> 0 | R7: =C7-Q7 -> 4800000
A8: 1.6 | B8: Maestro 1° Líneas | C8: 21000000 | D8: =SUMIFS(Costos_Extracontables!$D:$D, Costos_Extracontables!$E:$E, $B8, Costos_Extracontables!$C:$C, ">=2026-05-01", Costos_Extracontables!$C:$C, "<=2026-05-31") -> 0 | E8: =SUMIFS(Costos_Extracontables!$D:$D, Costos_Extracontables!$E:$E, $B8, Costos_Extracontables!$C:$C, ">=2026-06-01", Costos_Extracontables!$C:$C, "<=2026-06-31") -> 0 | I8: =SUM(D8:G8) -> 0 | J8: 0 | K8: =I8+J8 -> 0 | L8: =C8-K8 -> 21000000 | M8: 0 | N8: =C8*M8 -> 0 | O8: =N8-I8 -> 0 | P8: 0 | Q8: =K8+P8 -> 0 | R8: =C8-Q8 -> 21000000
A9: 1.7 | B9: Maestro 2° Líneas | C9: 7800000 | D9: =SUMIFS(Costos_Extracontables!$D:$D, Costos_Extracontables!$E:$E, $B9, Costos_Extracontables!$C:$C, ">=2026-05-01", Costos_Extracontables!$C:$C, "<=2026-05-31") -> 0 | E9: =SUMIFS(Costos_Extracontables!$D:$D, Costos_Extracontables!$E:$E, $B9, Costos_Extracontables!$C:$C, ">=2026-06-01", Costos_Extracontables!$C:$C, "<=2026-06-31") -> 0 | I9: =SUM(D9:G9) -> 0 | J9: 0 | K9: =I9+J9 -> 0 | L9: =C9-K9 -> 7800000 | M9: 0 | N9: =C9*M9 -> 0 | O9: =N9-I9 -> 0 | P9: 0 | Q9: =K9+P9 -> 0 | R9: =C9-Q9 -> 7800000
A10: 1.8 | B10: Operador Camión Pluma | C10: 5700000 | D10: =SUMIFS(Costos_Extracontables!$D:$D, Costos_Extracontables!$E:$E, $B10, Costos_Extracontables!$C:$C, ">=2026-05-01", Costos_Extracontables!$C:$C, "<=2026-05-31") -> 0 | E10: =SUMIFS(Costos_Extracontables!$D:$D, Costos_Extracontables!$E:$E, $B10, Costos_Extracontables!$C:$C, ">=2026-06-01", Costos_Extracontables!$C:$C, "<=2026-06-31") -> 0 | I10: =SUM(D10:G10) -> 0 | J10: 0 | K10: =I10+J10 -> 0 | L10: =C10-K10 -> 5700000 | M10: 0 | N10: =C10*M10 -> 0 | O10: =N10-I10 -> 0 | P10: 0 | Q10: =K10+P10 -> 0 | R10: =C10-Q10 -> 5700000
A11: 1.9 | B11: Rigger | C11: 3900000 | D11: =SUMIFS(Costos_Extracontables!$D:$D, Costos_Extracontables!$E:$E, $B11, Costos_Extracontables!$C:$C, ">=2026-05-01", Costos_Extracontables!$C:$C, "<=2026-05-31") -> 0 | E11: =SUMIFS(Costos_Extracontables!$D:$D, Costos_Extracontables!$E:$E, $B11, Costos_Extracontables!$C:$C, ">=2026-06-01", Costos_Extracontables!$C:$C, "<=2026-06-31") -> 0 | I11: =SUM(D11:G11) -> 0 | J11: 0 | K11: =I11+J11 -> 0 | L11: =C11-K11 -> 3900000 | M11: 0 | N11: =C11*M11 -> 0 | O11: =N11-I11 -> 0 | P11: 0 | Q11: =K11+P11 -> 0 | R11: =C11-Q11 -> 3900000
A12: 2.0 | B12: MATERIALES E INSUMOS | C12: =SUM(C13:C15) -> 2956644.4 | D12: =SUM(D13:D15) -> 0 | E12: =SUM(E13:E15) -> 0 | F12: =SUM(F13:F15) -> 0 | G12: =SUM(G13:G15) -> 0 | H12: =SUM(H13:H15) -> 0 | I12: =SUM(D12:G12) -> 0 | J12: 0 | K12: =I12+J12 -> 0 | L12: =C12-K12 -> 2956644.4 | M12: 0 | N12: =C12*M12 -> 0 | O12: =N12-I12 -> 0 | P12: 0 | Q12: =K12+P12 -> 0 | R12: =C12-Q12 -> 2956644.4
A13: 2.1 | B13: Instalación y Equipamiento Oficina Faena | C13: 1509542.9 | D13: =SUMIFS(Costos_Extracontables!$D:$D, Costos_Extracontables!$E:$E, $B13, Costos_Extracontables!$C:$C, ">=2026-05-01", Costos_Extracontables!$C:$C, "<=2026-05-31") -> 0 | E13: =SUMIFS(Costos_Extracontables!$D:$D, Costos_Extracontables!$E:$E, $B13, Costos_Extracontables!$C:$C, ">=2026-06-01", Costos_Extracontables!$C:$C, "<=2026-06-31") -> 0 | I13: =SUM(D13:G13) -> 0 | J13: 0 | K13: =I13+J13 -> 0 | L13: =C13-K13 -> 1509542.9 | M13: 0 | N13: =C13*M13 -> 0 | O13: =N13-I13 -> 0 | P13: 0 | Q13: =K13+P13 -> 0 | R13: =C13-Q13 -> 1509542.9
A14: 2.2 | B14: Suministros Menores (Agua, Café, etc.) | C14: 631832.8 | D14: =SUMIFS(Costos_Extracontables!$D:$D, Costos_Extracontables!$E:$E, $B14, Costos_Extracontables!$C:$C, ">=2026-05-01", Costos_Extracontables!$C:$C, "<=2026-05-31") -> 0 | E14: =SUMIFS(Costos_Extracontables!$D:$D, Costos_Extracontables!$E:$E, $B14, Costos_Extracontables!$C:$C, ">=2026-06-01", Costos_Extracontables!$C:$C, "<=2026-06-31") -> 0 | I14: =SUM(D14:G14) -> 0 | J14: 0 | K14: =I14+J14 -> 0 | L14: =C14-K14 -> 631832.8 | M14: 0 | N14: =C14*M14 -> 0 | O14: =N14-I14 -> 0 | P14: 0 | Q14: =K14+P14 -> 0 | R14: =C14-Q14 -> 631832.8
A15: 2.3 | B15: Implementos HSEC (Extintor, Camilla) | C15: 815268.67 | D15: =SUMIFS(Costos_Extracontables!$D:$D, Costos_Extracontables!$E:$E, $B15, Costos_Extracontables!$C:$C, ">=2026-05-01", Costos_Extracontables!$C:$C, "<=2026-05-31") -> 0 | E15: =SUMIFS(Costos_Extracontables!$D:$D, Costos_Extracontables!$E:$E, $B15, Costos_Extracontables!$C:$C, ">=2026-06-01", Costos_Extracontables!$C:$C, "<=2026-06-31") -> 0 | I15: =SUM(D15:G15) -> 0 | J15: 0 | K15: =I15+J15 -> 0 | L15: =C15-K15 -> 815268.67 | M15: 0 | N15: =C15*M15 -> 0 | O15: =N15-I15 -> 0 | P15: 0 | Q15: =K15+P15 -> 0 | R15: =C15-Q15 -> 815268.67
A16: 3.0 | B16: EQUIPOS Y MAQUINARIA | C16: =SUM(C17:C21) -> 57720797 | D16: =SUM(D17:D21) -> 0 | E16: =SUM(E17:E21) -> 0 | F16: =SUM(F17:F21) -> 0 | G16: =SUM(G17:G21) -> 0 | H16: =SUM(H17:H21) -> 0 | I16: =SUM(D16:G16) -> 0 | J16: 0 | K16: =I16+J16 -> 0 | L16: =C16-K16 -> 57720797 | M16: 0 | N16: =C16*M16 -> 0 | O16: =N16-I16 -> 0 | P16: 0 | Q16: =K16+P16 -> 0 | R16: =C16-Q16 -> 57720797
A17: 3.1 | B17: Arriendo Camionetas 4x4 | C17: 19000000 | D17: =SUMIFS(Costos_Extracontables!$D:$D, Costos_Extracontables!$E:$E, $B17, Costos_Extracontables!$C:$C, ">=2026-05-01", Costos_Extracontables!$C:$C, "<=2026-05-31") -> 0 | E17: =SUMIFS(Costos_Extracontables!$D:$D, Costos_Extracontables!$E:$E, $B17, Costos_Extracontables!$C:$C, ">=2026-06-01", Costos_Extracontables!$C:$C, "<=2026-06-31") -> 0 | I17: =SUM(D17:G17) -> 0 | J17: 0 | K17: =I17+J17 -> 0 | L17: =C17-K17 -> 19000000 | M17: 0 | N17: =C17*M17 -> 0 | O17: =N17-I17 -> 0 | P17: 0 | Q17: =K17+P17 -> 0 | R17: =C17-Q17 -> 19000000
A18: 3.2 | B18: Arriendo Camión Pluma 20 Ton | C18: 22500000 | D18: =SUMIFS(Costos_Extracontables!$D:$D, Costos_Extracontables!$E:$E, $B18, Costos_Extracontables!$C:$C, ">=2026-05-01", Costos_Extracontables!$C:$C, "<=2026-05-31") -> 0 | E18: =SUMIFS(Costos_Extracontables!$D:$D, Costos_Extracontables!$E:$E, $B18, Costos_Extracontables!$C:$C, ">=2026-06-01", Costos_Extracontables!$C:$C, "<=2026-06-31") -> 0 | I18: =SUM(D18:G18) -> 0 | J18: 0 | K18: =I18+J18 -> 0 | L18: =C18-K18 -> 22500000 | M18: 0 | N18: =C18*M18 -> 0 | O18: =N18-I18 -> 0 | P18: 0 | Q18: =K18+P18 -> 0 | R18: =C18-Q18 -> 22500000
A19: 3.3 | B19: Equipos HTLS (Prensa, Alzabobina, Cordina) | C19: 10507320 | D19: =SUMIFS(Costos_Extracontables!$D:$D, Costos_Extracontables!$E:$E, $B19, Costos_Extracontables!$C:$C, ">=2026-05-01", Costos_Extracontables!$C:$C, "<=2026-05-31") -> 0 | E19: =SUMIFS(Costos_Extracontables!$D:$D, Costos_Extracontables!$E:$E, $B19, Costos_Extracontables!$C:$C, ">=2026-06-01", Costos_Extracontables!$C:$C, "<=2026-06-31") -> 0 | I19: =SUM(D19:G19) -> 0 | J19: 0 | K19: =I19+J19 -> 0 | L19: =C19-K19 -> 10507320 | M19: 0 | N19: =C19*M19 -> 0 | O19: =N19-I19 -> 0 | P19: 0 | Q19: =K19+P19 -> 0 | R19: =C19-Q19 -> 10507320
A20: 3.4 | B20: Generador 30 kVA | C20: 2043010.8 | D20: =SUMIFS(Costos_Extracontables!$D:$D, Costos_Extracontables!$E:$E, $B20, Costos_Extracontables!$C:$C, ">=2026-05-01", Costos_Extracontables!$C:$C, "<=2026-05-31") -> 0 | E20: =SUMIFS(Costos_Extracontables!$D:$D, Costos_Extracontables!$E:$E, $B20, Costos_Extracontables!$C:$C, ">=2026-06-01", Costos_Extracontables!$C:$C, "<=2026-06-31") -> 0 | I20: =SUM(D20:G20) -> 0 | J20: 0 | K20: =I20+J20 -> 0 | L20: =C20-K20 -> 2043010.8 | M20: 0 | N20: =C20*M20 -> 0 | O20: =N20-I20 -> 0 | P20: 0 | Q20: =K20+P20 -> 0 | R20: =C20-Q20 -> 2043010.8
A21: 3.5 | B21: Herramientas e Implementos Menores (Escalas, Señalética) | C21: 3670465.9 | D21: =SUMIFS(Costos_Extracontables!$D:$D, Costos_Extracontables!$E:$E, $B21, Costos_Extracontables!$C:$C, ">=2026-05-01", Costos_Extracontables!$C:$C, "<=2026-05-31") -> 0 | E21: =SUMIFS(Costos_Extracontables!$D:$D, Costos_Extracontables!$E:$E, $B21, Costos_Extracontables!$C:$C, ">=2026-06-01", Costos_Extracontables!$C:$C, "<=2026-06-31") -> 0 | I21: =SUM(D21:G21) -> 0 | J21: 0 | K21: =I21+J21 -> 0 | L21: =C21-K21 -> 3670465.9 | M21: 0 | N21: =C21*M21 -> 0 | O21: =N21-I21 -> 0 | P21: 0 | Q21: =K21+P21 -> 0 | R21: =C21-Q21 -> 3670465.9
A22: 4.0 | B22: SUBCONTRATOS | C22: =SUM(C23:C25) -> 4510650 | D22: =SUM(D23:D25) -> 0 | E22: =SUM(E23:E25) -> 0 | F22: =SUM(F23:F25) -> 0 | G22: =SUM(G23:G25) -> 0 | H22: =SUM(H23:H25) -> 0 | I22: =SUM(D22:G22) -> 0 | J22: 0 | K22: =I22+J22 -> 0 | L22: =C22-K22 -> 4510650 | M22: 0 | N22: =C22*M22 -> 0 | O22: =N22-I22 -> 0 | P22: 0 | Q22: =K22+P22 -> 0 | R22: =C22-Q22 -> 4510650
A23: 4.1 | B23: Arriendo Container Oficina | C23: 710650 | D23: =SUMIFS(Costos_Extracontables!$D:$D, Costos_Extracontables!$E:$E, $B23, Costos_Extracontables!$C:$C, ">=2026-05-01", Costos_Extracontables!$C:$C, "<=2026-05-31") -> 0 | E23: =SUMIFS(Costos_Extracontables!$D:$D, Costos_Extracontables!$E:$E, $B23, Costos_Extracontables!$C:$C, ">=2026-06-01", Costos_Extracontables!$C:$C, "<=2026-06-31") -> 0 | I23: =SUM(D23:G23) -> 0 | J23: 0 | K23: =I23+J23 -> 0 | L23: =C23-K23 -> 710650 | M23: 0 | N23: =C23*M23 -> 0 | O23: =N23-I23 -> 0 | P23: 0 | Q23: =K23+P23 -> 0 | R23: =C23-Q23 -> 710650
A24: 4.2 | B24: Arriendo Baños Químicos | C24: 1800000 | D24: =SUMIFS(Costos_Extracontables!$D:$D, Costos_Extracontables!$E:$E, $B24, Costos_Extracontables!$C:$C, ">=2026-05-01", Costos_Extracontables!$C:$C, "<=2026-05-31") -> 0 | E24: =SUMIFS(Costos_Extracontables!$D:$D, Costos_Extracontables!$E:$E, $B24, Costos_Extracontables!$C:$C, ">=2026-06-01", Costos_Extracontables!$C:$C, "<=2026-06-31") -> 0 | I24: =SUM(D24:G24) -> 0 | J24: 0 | K24: =I24+J24 -> 0 | L24: =C24-K24 -> 1800000 | M24: 0 | N24: =C24*M24 -> 0 | O24: =N24-I24 -> 0 | P24: 0 | Q24: =K24+P24 -> 0 | R24: =C24-Q24 -> 1800000
A25: 4.3 | B25: Fletes y Transporte | C25: 2000000 | D25: =SUMIFS(Costos_Extracontables!$D:$D, Costos_Extracontables!$E:$E, $B25, Costos_Extracontables!$C:$C, ">=2026-05-01", Costos_Extracontables!$C:$C, "<=2026-05-31") -> 0 | E25: =SUMIFS(Costos_Extracontables!$D:$D, Costos_Extracontables!$E:$E, $B25, Costos_Extracontables!$C:$C, ">=2026-06-01", Costos_Extracontables!$C:$C, "<=2026-06-31") -> 0 | I25: =SUM(D25:G25) -> 0 | J25: 0 | K25: =I25+J25 -> 0 | L25: =C25-K25 -> 2000000 | M25: 0 | N25: =C25*M25 -> 0 | O25: =N25-I25 -> 0 | P25: 0 | Q25: =K25+P25 -> 0 | R25: =C25-Q25 -> 2000000
A26: 5.0 | B26: ASESORÍA TÉCNICA CTC GLOBAL | C26: =SUM(C27:C29) -> 17980000 | D26: =SUM(D27:D29) -> 0 | E26: =SUM(E27:E29) -> 0 | F26: =SUM(F27:F29) -> 0 | G26: =SUM(G27:G29) -> 0 | H26: =SUM(H27:H29) -> 0 | I26: =SUM(D26:G26) -> 0 | J26: 0 | K26: =I26+J26 -> 0 | L26: =C26-K26 -> 17980000 | M26: 0 | N26: =C26*M26 -> 0 | O26: =N26-I26 -> 0 | P26: 0 | Q26: =K26+P26 -> 0 | R26: =C26-Q26 -> 17980000
A27: 5.1 | B27: Servicios de Asesoría y Standby | C27: 14800000 | D27: =SUMIFS(Costos_Extracontables!$D:$D, Costos_Extracontables!$E:$E, $B27, Costos_Extracontables!$C:$C, ">=2026-05-01", Costos_Extracontables!$C:$C, "<=2026-05-31") -> 0 | E27: =SUMIFS(Costos_Extracontables!$D:$D, Costos_Extracontables!$E:$E, $B27, Costos_Extracontables!$C:$C, ">=2026-06-01", Costos_Extracontables!$C:$C, "<=2026-06-31") -> 0 | I27: =SUM(D27:G27) -> 0 | J27: 0 | K27: =I27+J27 -> 0 | L27: =C27-K27 -> 14800000 | M27: 0 | N27: =C27*M27 -> 0 | O27: =N27-I27 -> 0 | P27: 0 | Q27: =K27+P27 -> 0 | R27: =C27-Q27 -> 14800000
A28: 5.2 | B28: Logística y Viáticos Asesor | C28: 1680000 | D28: =SUMIFS(Costos_Extracontables!$D:$D, Costos_Extracontables!$E:$E, $B28, Costos_Extracontables!$C:$C, ">=2026-05-01", Costos_Extracontables!$C:$C, "<=2026-05-31") -> 0 | E28: =SUMIFS(Costos_Extracontables!$D:$D, Costos_Extracontables!$E:$E, $B28, Costos_Extracontables!$C:$C, ">=2026-06-01", Costos_Extracontables!$C:$C, "<=2026-06-31") -> 0 | I28: =SUM(D28:G28) -> 0 | J28: 0 | K28: =I28+J28 -> 0 | L28: =C28-K28 -> 1680000 | M28: 0 | N28: =C28*M28 -> 0 | O28: =N28-I28 -> 0 | P28: 0 | Q28: =K28+P28 -> 0 | R28: =C28-Q28 -> 1680000
A29: 5.3 | B29: EPP Asesor Especialista | C29: 1500000 | D29: =SUMIFS(Costos_Extracontables!$D:$D, Costos_Extracontables!$E:$E, $B29, Costos_Extracontables!$C:$C, ">=2026-05-01", Costos_Extracontables!$C:$C, "<=2026-05-31") -> 0 | E29: =SUMIFS(Costos_Extracontables!$D:$D, Costos_Extracontables!$E:$E, $B29, Costos_Extracontables!$C:$C, ">=2026-06-01", Costos_Extracontables!$C:$C, "<=2026-06-31") -> 0 | I29: =SUM(D29:G29) -> 0 | J29: 0 | K29: =I29+J29 -> 0 | L29: =C29-K29 -> 1500000 | M29: 0 | N29: =C29*M29 -> 0 | O29: =N29-I29 -> 0 | P29: 0 | Q29: =K29+P29 -> 0 | R29: =C29-Q29 -> 1500000
A30: 6.0 | B30: GASTOS GENERALES Y OPERACIONALES | C30: =SUM(C31:C36) -> 80209991 | D30: =SUM(D31:D36) -> 200000 | E30: =SUM(E31:E36) -> 0 | F30: =SUM(F31:F36) -> 0 | G30: =SUM(G31:G36) -> 0 | H30: =SUM(H31:H36) -> 0 | I30: =SUM(D30:G30) -> 200000 | J30: 0 | K30: =I30+J30 -> 200000 | L30: =C30-K30 -> 80009991 | M30: 0 | N30: =C30*M30 -> 0 | O30: =N30-I30 -> -200000 | P30: 0 | Q30: =K30+P30 -> 200000 | R30: =C30-Q30 -> 80009991
A31: 6.1 | B31: Logística: Alojamiento MOD/MOI/Staff | C31: 20800000 | D31: =SUMIFS(Costos_Extracontables!$D:$D, Costos_Extracontables!$E:$E, $B31, Costos_Extracontables!$C:$C, ">=2026-05-01", Costos_Extracontables!$C:$C, "<=2026-05-31") -> 200000 | E31: =SUMIFS(Costos_Extracontables!$D:$D, Costos_Extracontables!$E:$E, $B31, Costos_Extracontables!$C:$C, ">=2026-06-01", Costos_Extracontables!$C:$C, "<=2026-06-31") -> 0 | I31: =SUM(D31:G31) -> 200000 | J31: 0 | K31: =I31+J31 -> 200000 | L31: =C31-K31 -> 20600000 | M31: 0 | N31: =C31*M31 -> 0 | O31: =N31-I31 -> -200000 | P31: 0 | Q31: =K31+P31 -> 200000 | R31: =C31-Q31 -> 20600000
A32: 6.2 | B32: Logística: Alimentación MOD/MOI/Staff | C32: 11400000 | D32: =SUMIFS(Costos_Extracontables!$D:$D, Costos_Extracontables!$E:$E, $B32, Costos_Extracontables!$C:$C, ">=2026-05-01", Costos_Extracontables!$C:$C, "<=2026-05-31") -> 0 | E32: =SUMIFS(Costos_Extracontables!$D:$D, Costos_Extracontables!$E:$E, $B32, Costos_Extracontables!$C:$C, ">=2026-06-01", Costos_Extracontables!$C:$C, "<=2026-06-31") -> 0 | I32: =SUM(D32:G32) -> 0 | J32: 0 | K32: =I32+J32 -> 0 | L32: =C32-K32 -> 11400000 | M32: 0 | N32: =C32*M32 -> 0 | O32: =N32-I32 -> 0 | P32: 0 | Q32: =K32+P32 -> 0 | R32: =C32-Q32 -> 11400000
A33: 6.3 | B33: Logística: Pasajes y Traslados | C33: 12900000 | D33: =SUMIFS(Costos_Extracontables!$D:$D, Costos_Extracontables!$E:$E, $B33, Costos_Extracontables!$C:$C, ">=2026-05-01", Costos_Extracontables!$C:$C, "<=2026-05-31") -> 0 | E33: =SUMIFS(Costos_Extracontables!$D:$D, Costos_Extracontables!$E:$E, $B33, Costos_Extracontables!$C:$C, ">=2026-06-01", Costos_Extracontables!$C:$C, "<=2026-06-31") -> 0 | I33: =SUM(D33:G33) -> 0 | J33: 0 | K33: =I33+J33 -> 0 | L33: =C33-K33 -> 12900000 | M33: 0 | N33: =C33*M33 -> 0 | O33: =N33-I33 -> 0 | P33: 0 | Q33: =K33+P33 -> 0 | R33: =C33-Q33 -> 12900000
A34: 6.4 | B34: Costo Operativo Equipos (Combustible, etc.) | C34: 3989991 | D34: =SUMIFS(Costos_Extracontables!$D:$D, Costos_Extracontables!$E:$E, $B34, Costos_Extracontables!$C:$C, ">=2026-05-01", Costos_Extracontables!$C:$C, "<=2026-05-31") -> 0 | E34: =SUMIFS(Costos_Extracontables!$D:$D, Costos_Extracontables!$E:$E, $B34, Costos_Extracontables!$C:$C, ">=2026-06-01", Costos_Extracontables!$C:$C, "<=2026-06-31") -> 0 | I34: =SUM(D34:G34) -> 0 | J34: 0 | K34: =I34+J34 -> 0 | L34: =C34-K34 -> 3989991 | M34: 0 | N34: =C34*M34 -> 0 | O34: =N34-I34 -> 0 | P34: 0 | Q34: =K34+P34 -> 0 | R34: =C34-Q34 -> 3989991
A35: 6.5 | B35: EPP y Ropa de Trabajo Personal (Directo e Ind.) | C35: 25600000 | D35: =SUMIFS(Costos_Extracontables!$D:$D, Costos_Extracontables!$E:$E, $B35, Costos_Extracontables!$C:$C, ">=2026-05-01", Costos_Extracontables!$C:$C, "<=2026-05-31") -> 0 | E35: =SUMIFS(Costos_Extracontables!$D:$D, Costos_Extracontables!$E:$E, $B35, Costos_Extracontables!$C:$C, ">=2026-06-01", Costos_Extracontables!$C:$C, "<=2026-06-31") -> 0 | I35: =SUM(D35:G35) -> 0 | J35: 0 | K35: =I35+J35 -> 0 | L35: =C35-K35 -> 25600000 | M35: 0 | N35: =C35*M35 -> 0 | O35: =N35-I35 -> 0 | P35: 0 | Q35: =K35+P35 -> 0 | R35: =C35-Q35 -> 25600000
A36: 6.6 | B36: Certificaciones Externas | C36: 5520000 | D36: =SUMIFS(Costos_Extracontables!$D:$D, Costos_Extracontables!$E:$E, $B36, Costos_Extracontables!$C:$C, ">=2026-05-01", Costos_Extracontables!$C:$C, "<=2026-05-31") -> 0 | E36: =SUMIFS(Costos_Extracontables!$D:$D, Costos_Extracontables!$E:$E, $B36, Costos_Extracontables!$C:$C, ">=2026-06-01", Costos_Extracontables!$C:$C, "<=2026-06-31") -> 0 | I36: =SUM(D36:G36) -> 0 | J36: 0 | K36: =I36+J36 -> 0 | L36: =C36-K36 -> 5520000 | M36: 0 | N36: =C36*M36 -> 0 | O36: =N36-I36 -> 0 | P36: 0 | Q36: =K36+P36 -> 0 | R36: =C36-Q36 -> 5520000
A37: 7.0 | B37: IMPREVISTOS Y CONTINGENCIAS | C37: =SUM(C38) -> 26950000 | D37: =SUM(D38) -> 0 | E37: =SUM(E38) -> 0 | F37: =SUM(F38) -> 0 | G37: =SUM(G38) -> 0 | H37: =SUM(H38) -> 0 | I37: =SUM(D37:G37) -> 0 | J37: 0 | K37: =I37+J37 -> 0 | L37: =C37-K37 -> 26950000 | M37: 0 | N37: =C37*M37 -> 0 | O37: =N37-I37 -> 0 | P37: 0 | Q37: =K37+P37 -> 0 | R37: =C37-Q37 -> 26950000
A38: 7.1 | B38: Provisión Imprevistos (15 días) | C38: 26950000 | D38: =SUMIFS(Costos_Extracontables!$D:$D, Costos_Extracontables!$E:$E, $B38, Costos_Extracontables!$C:$C, ">=2026-05-01", Costos_Extracontables!$C:$C, "<=2026-05-31") -> 0 | E38: =SUMIFS(Costos_Extracontables!$D:$D, Costos_Extracontables!$E:$E, $B38, Costos_Extracontables!$C:$C, ">=2026-06-01", Costos_Extracontables!$C:$C, "<=2026-06-31") -> 0 | I38: =SUM(D38:G38) -> 0 | J38: 0 | K38: =I38+J38 -> 0 | L38: =C38-K38 -> 26950000 | M38: 0 | N38: =C38*M38 -> 0 | O38: =N38-I38 -> 0 | P38: 0 | Q38: =K38+P38 -> 0 | R38: =C38-Q38 -> 26950000
B39: TOTAL COSTOS | C39: =+C37+C30+C26+C22+C16+C12+C2 -> 2.5302808e+08 | D39: =+D37+D30+D26+D22+D16+D12+D2 -> 200000 | E39: =+E37+E30+E26+E22+E16+E12+E2 -> 0 | F39: =+F37+F30+F26+F22+F16+F12+F2 -> 0 | G39: =+G37+G30+G26+G22+G16+G12+G2 -> 0 | H39: =+H37+H30+H26+H22+H16+H12+H2 -> 0 | I39: =+I37+I30+I26+I22+I16+I12+I2 -> 200000 | J39: =+J37+J30+J26+J22+J16+J12+J2 -> 0 | ... L39: =+L37+L30+L26+L22+L16+L12+L2 -> 2.5282808e+08 | M39: =IF(C39>0,N39/C39,0) -> 0 | N39: =SUMIF(A2:A38, "*.0", N2:N38) -> 0 | O39: =SUMIF(A2:A38, "*.0", O2:O38) -> -200000 | P39: =SUMIF(A2:A38, "*.0", P2:P38) -> 0 | Q39: =SUMIF(A2:A38, "*.0", Q2:Q38) -> 200000 | R39: =SUMIF(A2:A38, "*.0", R2:R38) -> 2.5282808e+08
B40: TOTAL INGRESOS | C40: 3.84359e+08
...

Sheet Costos_Extracontables
A1: WBS | B1: Descripción del Costo | C1: Fecha (Mes) | D1: Monto Neto | E1: Clasificación (utilizar lista deplegable) | F1: Tipo de Costo | G1: Comentarios | H1: Registrado en Contabilidad
A2: 1 | B2: Estadia Capacitacion MOD + JC Santander - Iquique S25-29 Mayo | C2: 46143 | D2: =40000*5 -> 200000 | E2: Logística: Alojamiento MOD/MOI/Staff | F2: Factura Pago 30 días | H2: No
A3: 2 | B3: Examenes Iquique | H3: No
A4: 3 | B4: Coaching 3D CEIM | H4: No
A5: 4 | B5: Pasajes Iquique - Antofagasta Personal Directo | H5: No
A6: 5 | B6: Estadia Antofagasta Personal Directo | H6: No
A7: 6 | B7: Alimentacion Antofagasta Personal Directo | H7: No
A8: 7 | H8: No
A9: 8 | H9: No
A10: 9 | H10: No
A11: 10 | H11: No
A12: 11 | H12: No
A13: 12 | H13: No
A14: 13 | H14: No
A15: 14 | H15: No
A16: 15 | H16: No
A17: 16 | H17: No
A18: 17 | H18: No
A19: 18 | H19: No
... A137: 136 | H137: No
B138: TOTAL COSTOS | D138: =SUM(D2:D137) -> 200000

Sheet RRHH_Control
A1: ID | B1: Cargo | C1: Código | D1: Nombre | E1: Examen Méd. | F1: Test A&D | G1: Gran Altura Geografica | H1: Gran Altura Física | I1: Psicosenso. | J1: Aversión al Riesgo | K1: Indicadores Medidos en Aversion al Riesgo | L1: Adecuación a normas y procedimientos | M1: Capacidad de atención y concentración | N1: Capacidad para trabajar bajo presión | O1: Conducta precavida | P1: Control de impulsos | Q1: Disposición al aprendizaje y capacitación | R1: Estabilidad emocional | S1: Carta Oferta | T1: Documentos Solicitados STN | U1: Contrato / Anexo | V1: Ficha Trab. MEL | W1: Cert. Anteced. | X1: Cédula Ident. | Y1: Regl. Transp | Z1: Portal PMF | AA1: Coaching 3D | AB1: 3D-CEIM | AC1: Supervisor Izaje | AD1: Asistente Izaje | AE1: Lic. Rigger | AF1: Valid. Deloitte | AG1: Cursos Inatrans Lic. Interna Camionetas (3) | AH1: Lic. Operador | AI1: Avance HDR (%) | AJ1: % Cumpl. MEL | AK1: Estado Final | AL1: Semáforo | AM1: Cumplimiento Consolidado | AN1: Observaciones
A2: P01 | B2: Administrador Contrato | C2: ADM_01 | D2: Andrés Tebes | E2: Aprobado | F2: Aprobado | G2: Aprobado | H2: Aprobado | I2: Aprobado | J2: Aprobado | K2: =COUNTIF(L2:R2,"*OK*") & " de 7 ; " & ROUND(COUNTIF(L2:R2,"*OK*")/7*100,0) & "%" -> 7 de 7 ; 100% | L2: OK -Dentro de lo esperado | M2: OK -Dentro de lo esperado | N2: OK -Dentro de lo esperado | O2: OK -Dentro de lo esperado | P2: OK -Dentro de lo esperado | Q2: OK -Dentro de lo esperado | R2: OK -Dentro de lo esperado | S2: N/A | T2: N/A | U2: Aprobado | V2: N/A | W2: No Iniciado | X2: N/A | Y2: N/A | Z2: N/A | AA2: No Iniciado | AB2: No Iniciado | AC2: N/A | AD2: N/A | AE2: N/A | AF2: No Iniciado | AG2: 46177 | AH2: N/A | AI2: =IFERROR(HDR_Matriz!BI2, "Pendiente datos") -> 0 | AJ2: =IFERROR((COUNTIF(S2:AH2, "Aprobado")) / (12 - COUNTIF(S2:AH2, "N/A")), "Pendiente datos") -> 0.5 | AK2: En proceso | AL2: =IFERROR(IF(AK2="Acreditado", "Verde", IF(AK2="En Proceso", "Amarillo", "Rojo")), "Pendiente datos") -> Amarillo | AM2: =IFERROR(AVERAGE(AJ2, AI2), "Pendiente datos") -> 0.25 | AN2: Sincronizado
A3: P02 | B3: Asesor de Seguridad | C3: HSEC_01 | D3: Juan Carlos Santander | E3: Aprobado | F3: Aprobado | G3: Aprobado | H3: Aprobado | I3: Aprobado | J3: Aprobado | K3: =COUNTIF(L3:R3,"*OK*") & " de 7 ; " & ROUND(COUNTIF(L3:R3,"*OK*")/7*100,0) & "%" -> 7 de 7 ; 100% | L3: OK -Dentro de lo esperado | M3: OK -Dentro de lo esperado | N3: OK -Dentro de lo esperado | O3: OK -Dentro de lo esperado | P3: OK -Dentro de lo esperado | Q3: OK -Dentro de lo esperado | R3: OK -Dentro de lo esperado | S3: N/A | T3: N/A | U3: Aprobado | V3: N/A | W3: No Iniciado | X3: N/A | Y3: N/A | Z3: N/A | AA3: No Iniciado | AB3: No Iniciado | AC3: N/A | AD3: N/A | AE3: N/A | AF3: No Iniciado | AG3: 46184 | AH3: N/A | AI3: =IFERROR(HDR_Matriz!BI3, "Pendiente datos") -> 0 | AJ3: =IFERROR((COUNTIF(S3:AH3, "Aprobado")) / (12 - COUNTIF(S3:AH3, "N/A")), "Pendiente datos") -> 0.5 | AK3: En proceso | AL3: =IFERROR(IF(AK3="Acreditado", "Verde", IF(AK3="En Proceso", "Amarillo", "Rojo")), "Pendiente datos") -> Amarillo | AM3: =IFERROR(AVERAGE(AJ3, AI3), "Pendiente datos") -> 0.25 | AN3: Sincronizado
A4: P03 | B4: Jefe de Terreno | C4: JT_01 | D4: Leonel Sanchez | E4: Aprobado | F4: Aprobado | G4: Aprobado | H4: Aprobado | I4: Aprobado | J4: Aprobado | K4: =COUNTIF(L4:R4,"*OK*") & " de 7 ; " & ROUND(COUNTIF(L4:R4,"*OK*")/7*100,0) & "%" -> 7 de 7 ; 100% | L4: OK -Dentro de lo esperado | M4: OK -Dentro de lo esperado | N4: OK -Dentro de lo esperado | O4: OK -Dentro de lo esperado | P4: OK -Dentro de lo esperado | Q4: OK -Dentro de lo esperado | R4: OK -Dentro de lo esperado | S4: N/A | T4: N/A | U4: Aprobado | V4: N/A | W4: N/A | X4: N/A | Y4: N/A | Z4: N/A | AA4: No Iniciado | AB4: 46181 | AC4: N/A | AD4: N/A | AE4: N/A | AF4: No Iniciado | AG4: N/A | AH4: N/A | AI4: =IFERROR(HDR_Matriz!BI4, "Pendiente datos") -> 0 | AJ4: =IFERROR((COUNTIF(S4:AH4, "Aprobado")) / (12 - COUNTIF(S4:AH4, "N/A")), "Pendiente datos") -> Pendiente datos | AK4: En proceso | AL4: =IFERROR(IF(AK4="Acreditado", "Verde", IF(AK4="En Proceso", "Amarillo", "Rojo")), "Pendiente datos") -> Amarillo | AM4: =IFERROR(AVERAGE(AJ4, AI4), "Pendiente datos") -> 0 | AN4: Sincronizado
A5: P04 | B5: Supervisor de Terreno | C5: SUP_01 | D5: Ulises Psijas | E5: Aprobado | F5: Aprobado | G5: Aprobado | H5: Aprobado | I5: Aprobado | J5: Aprobado | K5: =COUNTIF(L5:R5,"*OK*") & " de 7 ; " & ROUND(COUNTIF(L5:R5,"*OK*")/7*100,0) & "%" -> 7 de 7 ; 100% | L5: OK -Dentro de lo esperado | M5: OK -Dentro de lo esperado | N5: OK -Dentro de lo esperado | O5: OK -Dentro de lo esperado | P5: OK -Dentro de lo esperado | Q5: OK -Dentro de lo esperado | R5: OK -Dentro de lo esperado | S5: Aprobado | T5: En proceso | U5: No Iniciado | V5: No Iniciado | W5: No Iniciado | X5: No Iniciado | Y5: No Iniciado | Z5: No Iniciado | AA5: No Iniciado | AB5: 46181 | AC5: 46178 | AD5: N/A | AE5: No Iniciado | AF5: No Iniciado | AG5: 46182 | AH5: N/A | AI5: =IFERROR(HDR_Matriz!BI5, "Pendiente datos") -> 0 | AJ5: =IFERROR((COUNTIF(S5:AH5, "Aprobado")) / (12 - COUNTIF(S5:AH5, "N/A")), "Pendiente datos") -> 0.1 | AK5: En proceso | AL5: =IFERROR(IF(AK5="Acreditado", "Verde", IF(AK5="En Proceso", "Amarillo", "Rojo")), "Pendiente datos") -> Amarillo | AM5: =IFERROR(AVERAGE(AJ5, AI5), "Pendiente datos") -> 0.05 | AN5: Sincronizado
A6: P05 | B6: Encargado Administrativo | C6: ADM_02 | D6: Jesenia Tapia | E6: Aprobado | F6: Aprobado | G6: Aprobado | H6: Aprobado | I6: Aprobado | J6: Aprobado | K6: =COUNTIF(L6:R6,"*OK*") & " de 7 ; " & ROUND(COUNTIF(L6:R6,"*OK*")/7*100,0) & "%" -> 7 de 7 ; 100% | L6: OK -Dentro de lo esperado | M6: OK -Dentro de lo esperado | N6: OK -Dentro de lo esperado | O6: OK -Dentro de lo esperado | P6: OK -Dentro de lo esperado | Q6: OK -Dentro de lo esperado | R6: OK -Dentro de lo esperado | S6: Aprobado | T6: No Iniciado | U6: Aprobado | V6: No Iniciado | W6: No Iniciado | X6: No Iniciado | Y6: No Iniciado | Z6: No Iniciado | AA6: No Iniciado | AB6: N/A | AC6: N/A | AD6: N/A | AE6: N/A | AF6: No Iniciado | AG6: N/A | AH6: N/A | AI6: =IFERROR(HDR_Matriz!BI6, "Pendiente datos") -> 0 | AJ6: =IFERROR((COUNTIF(S6:AH6, "Aprobado")) / (12 - COUNTIF(S6:AH6, "N/A")), "Pendiente datos") -> 0.33333333 | AK6: En proceso | AL6: =IFERROR(IF(AK6="Acreditado", "Verde", IF(AK6="En Proceso", "Amarillo", "Rojo")), "Pendiente datos") -> Amarillo | AM6: =IFERROR(AVERAGE(AJ6, AI6), "Pendiente datos") -> 0.16666667 | AN6: Sincronizado
A7: P06 | B7: Topógrafo | C7: TOPO_01 | D7: Manuel Tapia | E7: Aprobado | F7: Aprobado | G7: Aprobado | H7: Aprobado | I7: N/A | J7: Aprobado | K7: N/A | L7: OK -Dentro de lo esperado | M7: OK -Dentro de lo esperado | N7: OK -Dentro de lo esperado | O7: OK -Dentro de lo esperado | P7: OK -Dentro de lo esperado | Q7: OK -Dentro de lo esperado | R7: OK -Dentro de lo esperado | S7: Aprobado | T7: Aprobado | U7: Aprobado | V7: Aprobado | W7: Aprobado | X7: Aprobado | Y7: No Iniciado | Z7: No Iniciado | AA7: Aprobado | AB7: N/A | AC7: N/A | AD7: N/A | AE7: N/A | AF7: No Iniciado | AG7: N/A | AH7: N/A | AI7: =IFERROR(HDR_Matriz!BI7, "Pendiente datos") -> 0 | AJ7: =IFERROR((COUNTIF(S7:AH7, "Aprobado")) / (12 - COUNTIF(S7:AH7, "N/A")), "Pendiente datos") -> 1.1666667 | AK7: En proceso | AL7: =IFERROR(IF(AK7="Acreditado", "Verde", IF(AK7="En Proceso", "Amarillo", "Rojo")), "Pendiente datos") -> Amarillo | AM7: =IFERROR(AVERAGE(AJ7, AI7), "Pendiente datos") -> 0.58333333 | AN7: Sincronizado
A8: P07 | B8: Maestro 1° Líneas (Interno Alarife) | C8: M1_01 | D8: Orlando Maita | E8: Aprobado | F8: Aprobado | G8: Aprobado | H8: Aprobado | I8: N/A | J8: Aprobado | K8: =COUNTIF(L8:R8,"*OK*") & " de 7 ; " & ROUND(COUNTIF(L8:R8,"*OK*")/7*100,0) & "%" -> 7 de 7 ; 100% | L8: OK -Dentro de lo esperado | M8: OK -Dentro de lo esperado | N8: OK -Dentro de lo esperado | O8: OK -Dentro de lo esperado | P8: OK -Dentro de lo esperado | Q8: OK -Dentro de lo esperado | R8: OK -Dentro de lo esperado | S8: No Iniciado | T8: No Iniciado | U8: No Iniciado | V8: No Iniciado | W8: Aprobado | X8: No Iniciado | Y8: No Iniciado | Z8: No Iniciado | AA8: Aprobado | AB8: 46178 | AC8: N/A | AD8: N/A | AE8: N/A | AF8: No Iniciado | AG8: N/A | AH8: N/A | AI8: =IFERROR(HDR_Matriz!BI8, "Pendiente datos") -> 0 | AJ8: =IFERROR((COUNTIF(S8:AH8, "Aprobado")) / (12 - COUNTIF(S8:AH8, "N/A")), "Pendiente datos") -> 0.28571429 | AK8: En proceso | AL8: =IFERROR(IF(AK8="Acreditado", "Verde", IF(AK8="En Proceso", "Amarillo", "Rojo")), "Pendiente datos") -> Amarillo | AM8: =IFERROR(AVERAGE(AJ8, AI8), "Pendiente datos") -> 0.14285714 | AN8: Sincronizado
A9: P08 | B9: Maestro 1° Líneas | C9: M1_01 | D9: Wilmer Chambi | E9: Aprobado | F9: Aprobado | G9: Aprobado | H9: Aprobado | I9: N/A | J9: Aprobado | K9: =COUNTIF(L9:R9,"*OK*") & " de 7 ; " & ROUND(COUNTIF(L9:R9,"*OK*")/7*100,0) & "%" -> 7 de 7 ; 100% | L9: OK -Dentro de lo esperado | M9: OK -Dentro de lo esperado | N9: OK -Dentro de lo esperado | O9: OK -Dentro de lo esperado | P9: OK -Dentro de lo esperado | Q9: OK -Dentro de lo esperado | R9: OK -Dentro de lo esperado | S9: Aprobado | T9: No Iniciado | U9: Aprobado | V9: Aprobado | W9: Aprobado | X9: No Iniciado | Y9: No Iniciado | Z9: No Iniciado | AA9: Aprobado | AB9: 46177 | AC9: 46184 | AD9: N/A | AE9: No Iniciado | AF9: No Iniciado | AG9: N/A | AH9: N/A | AI9: =IFERROR(HDR_Matriz!BI9, "Pendiente datos") -> 0 | AJ9: =IFERROR((COUNTIF(S9:AH9, "Aprobado")) / (12 - COUNTIF(S9:AH9, "N/A")), "Pendiente datos") -> 0.55555556 | AK9: En proceso | AL9: =IFERROR(IF(AK9="Acreditado", "Verde", IF(AK9="En Proceso", "Amarillo", "Rojo")), "Pendiente datos") -> Amarillo | AM9: =IFERROR(AVERAGE(AJ9, AI9), "Pendiente datos") -> 0.27777778 | AN9: Sincronizado
A10: P19 | B10: Maestro 1° Líneas | C10: M1_02 | D10: David Flores | E10: Aprobado | F10: Aprobado | G10: Aprobado | H10: Aprobado | I10: Aprobado | J10: Aprobado | K10: 7 de 7 ; 100% | L10: OK -Dentro de lo esperado | M10: OK -Dentro de lo esperado | N10: OK -Dentro de lo esperado | O10: OK -Dentro de lo esperado | P10: OK -Dentro de lo esperado | Q10: OK -Dentro de lo esperado | R10: OK -Dentro de lo esperado | S10: En proceso | T10: No Iniciado | U10: No Iniciado | V10: No Iniciado | W10: Aprobado | X10: No Iniciado | Y10: No Iniciado | Z10: No Iniciado | AA10: Aprobado | AB10: 46177 | AC10: N/A | AD10: N/A | AE10: No Iniciado | AF10: No Iniciado | AG10: N/A | AH10: N/A | AI10: 0 | AJ10: 0 | AK10: En proceso | AL10: Amarillo | AM10: 0 | AN10: Sincronizado
A11: P10 | B11: Maestro 1° Líneas | C11: M1_03 | D11: Wilber Corrales | E11: Aprobado | F11: Aprobado | G11: Aprobado | H11: Aprobado | I11: N/A | J11: Aprobado | K11: =COUNTIF(L11:R11,"*OK*") & " de 7 ; " & ROUND(COUNTIF(L11:R11,"*OK*")/7*100,0) & "%" -> 7 de 7 ; 100% | L11: OK -Dentro de lo esperado | M11: OK -Dentro de lo esperado | N11: OK -Dentro de lo esperado | O11: OK -Dentro de lo esperado | P11: OK -Dentro de lo esperado | Q11: OK -Dentro de lo esperado | R11: OK -Dentro de lo esperado | S11: En proceso | T11: No Iniciado | U11: No Iniciado | V11: No Iniciado | W11: Aprobado | X11: No Iniciado | Y11: No Iniciado | Z11: No Iniciado | AA11: Aprobado | AB11: 46178 | AC11: N/A | AD11: N/A | AE11: N/A | AF11: No Iniciado | AG11: N/A | AH11: N/A | AI11: =IFERROR(HDR_Matriz!BI11, "Pendiente datos") -> 0 | AJ11: =IFERROR((COUNTIF(S11:AH11, "Aprobado")) / (12 - COUNTIF(S11:AH11, "N/A")), "Pendiente datos") -> 0.28571429 | AK11: En proceso | AL11: =IFERROR(IF(AK11="Acreditado", "Verde", IF(AK11="En Proceso", "Amarillo", "Rojo")), "Pendiente datos") -> Amarillo | AM11: =IFERROR(AVERAGE(AJ11, AI11), "Pendiente datos") -> 0.14285714 | AN11: Sincronizado
A12: P11 | B12: Maestro 1° Líneas | C12: M1_04 | D12: Ronald Orellana | E12: Aprobado | F12: Aprobado | G12: Aprobado | H12: Aprobado | I12: N/A | J12: Aprobado | K12: =COUNTIF(L12:R12,"*OK*") & " de 7 ; " & ROUND(COUNTIF(L12:R12,"*OK*")/7*100,0) & "%" -> 7 de 7 ; 100% | L12: OK -Dentro de lo esperado | M12: OK -Dentro de lo esperado | N12: OK -Dentro de lo esperado | O12: OK -Dentro de lo esperado | P12: OK -Dentro de lo esperado | Q12: OK -Dentro de lo esperado | R12: OK -Dentro de lo esperado | S12: En proceso | T12: No Iniciado | U12: No Iniciado | V12: No Iniciado | W12: Aprobado | X12: No Iniciado | Y12: No Iniciado | Z12: No Iniciado | AA12: Aprobado | AB12: 46178 | AC12: N/A | AD12: N/A | AE12: N/A | AF12: No Iniciado | AG12: N/A | AH12: N/A | AI12: =IFERROR(HDR_Matriz!BI12, "Pendiente datos") -> 0 | AJ12: =IFERROR((COUNTIF(S12:AH12, "Aprobado")) / (12 - COUNTIF(S12:AH12, "N/A")), "Pendiente datos") -> 0.28571429 | AK12: En proceso | AL12: =IFERROR(IF(AK12="Acreditado", "Verde", IF(AK12="En Proceso", "Amarillo", "Rojo")), "Pendiente datos") -> Amarillo | AM12: =IFERROR(AVERAGE(AJ12, AI12), "Pendiente datos") -> 0.14285714 | AN12: Sincronizado
A13: P12 | B13: Maestro 1° Líneas | C13: M1_05 | D13: Maica Villca | E13: Aprobado | F13: Aprobado | G13: Aprobado | H13: Aprobado | I13: N/A | J13: Aprobado | K13: =COUNTIF(L13:R13,"*OK*") & " de 7 ; " & ROUND(COUNTIF(L13:R13,"*OK*")/7*100,0) & "%" -> 7 de 7 ; 100% | L13: OK -Dentro de lo esperado | M13: OK -Dentro de lo esperado | N13: OK -Dentro de lo esperado | O13: OK -Dentro de lo esperado | P13: OK -Dentro de lo esperado | Q13: OK -Dentro de lo esperado | R13: OK -Dentro de lo esperado | S13: Aprobado | T13: No Iniciado | U13: Aprobado | V13: No Iniciado | W13: Aprobado | X13: No Iniciado | Y13: No Iniciado | Z13: No Iniciado | AA13: Aprobado | AB13: 46177 | AC13: N/A | AD13: 46181 | AE13: N/A | AF13: No Iniciado | AG13: N/A | AH13: N/A | AI13: =IFERROR(HDR_Matriz!BI13, "Pendiente datos") -> 0 | AJ13: =IFERROR((COUNTIF(S13:AH13, "Aprobado")) / (12 - COUNTIF(S13:AH13, "N/A")), "Pendiente datos") -> 0.5 | AK13: En proceso | AL13: =IFERROR(IF(AK13="Acreditado", "Verde", IF(AK13="En Proceso", "Amarillo", "Rojo")), "Pendiente datos") -> Amarillo | AM13: =IFERROR(AVERAGE(AJ13, AI13), "Pendiente datos") -> 0.25 | AN13: Sincronizado
A14: P13 | B14: Maestro 1° Líneas | C14: M1_06 | D14: Fredy Arena | E14: Aprobado | F14: Aprobado | G14: Aprobado | H14: Aprobado | I14: N/A | J14: Aprobado | K14: =COUNTIF(L14:R14,"*OK*") & " de 7 ; " & ROUND(COUNTIF(L14:R14,"*OK*")/7*100,0) & "%" -> 7 de 7 ; 100% | L14: OK -Dentro de lo esperado | M14: OK -Dentro de lo esperado | N14: OK -Dentro de lo esperado | O14: OK -Dentro de lo esperado | P14: OK -Dentro de lo esperado | Q14: OK -Dentro de lo esperado | R14: OK -Dentro de lo esperado | S14: Aprobado | T14: No Iniciado | U14: Aprobado | V14: No Iniciado | W14: Aprobado | X14: No Iniciado | Y14: No Iniciado | Z14: No Iniciado | AA14: Aprobado | AB14: 46177 | AC14: N/A | AD14: 46181 | AE14: No Iniciado | AF14: No Iniciado | AG14: N/A | AH14: N/A | AI14: =IFERROR(HDR_Matriz!BI14, "Pendiente datos") -> 0 | AJ14: =IFERROR((COUNTIF(S14:AH14, "Aprobado")) / (12 - COUNTIF(S14:AH14, "N/A")), "Pendiente datos") -> 0.44444444 | AK14: En proceso | AL14: =IFERROR(IF(AK14="Acreditado", "Verde", IF(AK14="En Proceso", "Amarillo", "Rojo")), "Pendiente datos") -> Amarillo | AM14: =IFERROR(AVERAGE(AJ14, AI14), "Pendiente datos") -> 0.22222222 | AN14: Sincronizado
A15: P14 | B15: Maestro 2° Líneas | C15: M2_01 | D15: Roly Ipurani | E15: Aprobado | F15: Aprobado | G15: Aprobado | H15: Aprobado | I15: N/A | J15: Aprobado | K15: =COUNTIF(L15:R15,"*OK*") & " de 7 ; " & ROUND(COUNTIF(L15:R15,"*OK*")/7*100,0) & "%" -> 7 de 7 ; 100% | L15: OK -Dentro de lo esperado | M15: OK -Dentro de lo esperado | N15: OK -Dentro de lo esperado | O15: OK -Dentro de lo esperado | P15: OK -Dentro de lo esperado | Q15: OK -Dentro de lo esperado | R15: OK -Dentro de lo esperado | S15: En proceso | T15: No Iniciado | U15: No Iniciado | V15: No Iniciado | W15: Aprobado | X15: No Iniciado | Y15: No Iniciado | Z15: No Iniciado | AA15: Aprobado | AB15: 46178 | AC15: N/A | AD15: N/A | AE15: N/A | AF15: No Iniciado | AG15: N/A | AH15: N/A | AI15: =IFERROR(HDR_Matriz!BI15, "Pendiente datos") -> 0 | AJ15: =IFERROR((COUNTIF(S15:AH15, "Aprobado")) / (12 - COUNTIF(S15:AH15, "N/A")), "Pendiente datos") -> 0.28571429 | AK15: En proceso | AL15: =IFERROR(IF(AK15="Acreditado", "Verde", IF(AK15="En Proceso", "Amarillo", "Rojo")), "Pendiente datos") -> Amarillo | AM15: =IFERROR(AVERAGE(AJ15, AI15), "Pendiente datos") -> 0.14285714 | AN15: Sincronizado
A16: P15 | B16: Maestro 2° Líneas | C16: M2_02 | D16: Erasmo Castellon | E16: Aprobado | F16: Aprobado | G16: Aprobado | H16: Aprobado | I16: N/A | J16: Alterado | K16: =COUNTIF(L16:R16,"*OK*") & " de 7 ; " & ROUND(COUNTIF(L16:R16,"*OK*")/7*100,0) & "%" -> 4 de 7 ; 57% | L16: OK -Dentro de lo esperado | M16: OK -Dentro de lo esperado | N16: Obs. Bajo lo esperado | O16: OK -Dentro de lo esperado | P16: Obs. Bajo lo esperado | Q16: OK -Dentro de lo esperado | R16: Obs. Bajo lo esperado | S16: En proceso | T16: No Iniciado | U16: No Iniciado | V16: No Iniciado | W16: Aprobado | X16: No Iniciado | Y16: No Iniciado | Z16: No Iniciado | AA16: Aprobado | AB16: 46178 | AC16: N/A | AD16: N/A | AE16: N/A | AF16: No Iniciado | AG16: N/A | AH16: N/A | AI16: =IFERROR(HDR_Matriz!BI9, "Pendiente datos") -> 0 | AJ16: =IFERROR((COUNTIF(S16:AH16, "Aprobado")) / (12 - COUNTIF(S16:AH16, "N/A")), "Pendiente datos") -> 0.28571429 | AK16: En proceso | AL16: =IFERROR(IF(AK16="Acreditado", "Verde", IF(AK16="En Proceso", "Amarillo", "Rojo")), "Pendiente datos") -> Amarillo | AM16: =IFERROR(AVERAGE(AJ16, AI16), "Pendiente datos") -> 0.14285714 | AN16: Sincronizado
A17: P16 | B17: Operador | C17: OP_01 | D17: Matias Quiñenao | E17: Aprobado | F17: Aprobado | G17: Aprobado | H17: Aprobado | I17: Aprobado | J17: Aprobado | K17: =COUNTIF(L17:R17,"*OK*") & " de 7 ; " & ROUND(COUNTIF(L17:R17,"*OK*")/7*100,0) & "%" -> 7 de 7 ; 100% | L17: OK -Dentro de lo esperado | M17: OK -Dentro de lo esperado | N17: OK -Dentro de lo esperado | O17: OK -Dentro de lo esperado | P17: OK -Dentro de lo esperado | Q17: OK -Dentro de lo esperado | R17: OK -Dentro de lo esperado | S17: N/A | T17: Aprobado | U17: Aprobado | V17: No Iniciado | W17: Aprobado | X17: No Iniciado | Y17: No Iniciado | Z17: No Iniciado | AA17: No Iniciado | AB17: 46181 | AC17: N/A | AD17: Aprobado | AE17: N/A | AF17: No Iniciado | AG17: Aprobado | AH17: No Iniciado | AI17: =IFERROR(HDR_Matriz!BI17, "Pendiente datos") -> 0 | AJ17: =IFERROR((COUNTIF(S17:AH17, "Aprobado")) / (12 - COUNTIF(S17:AH17, "N/A")), "Pendiente datos") -> 0.55555556 | AK17: En proceso | AL17: =IFERROR(IF(AK17="Acreditado", "Verde", IF(AK17="En Proceso", "Amarillo", "Rojo")), "Pendiente datos") -> Amarillo | AM17: =IFERROR(AVERAGE(AJ17, AI17), "Pendiente datos") -> 0.27777778 | AN17: Sincronizado
A18: P17 | B18: Rigger | C18: RIG_01 | D18: Mauro Vega (OP1) Sebastian Morales (OP2) | E18: 46183 | F18: 46183 | G18: 46183 | H18: 46183 | I18: N/A | J18: 46183 | K18: =COUNTIF(L18:R18,"*OK*") & " de 7 ; " & ROUND(COUNTIF(L18:R18,"*OK*")/7*100,0) & "%" -> 0 de 7 ; 0% | S18: No Iniciado | T18: No Iniciado | U18: No Iniciado | V18: No Iniciado | W18: No Iniciado | X18: No Iniciado | Y18: No Iniciado | Z18: No Iniciado | AA18: No Iniciado | AB18: No Iniciado | AC18: N/A | AD18: N/A | AE18: No Iniciado | AF18: No Iniciado | AG18: N/A | AH18: N/A | AI18: =IFERROR(HDR_Matriz!BI18, "Pendiente datos") -> 0 | AJ18: =IFERROR((COUNTIF(S18:AH18, "Aprobado")) / (12 - COUNTIF(S18:AH18, "N/A")), "Pendiente datos") -> 0 | AK18: En proceso | AL18: =IFERROR(IF(AK18="Acreditado", "Verde", IF(AK18="En Proceso", "Amarillo", "Rojo")), "Pendiente datos") -> Amarillo | AM18: =IFERROR(AVERAGE(AJ18, AI18), "Pendiente datos") -> 0 | AN18: Sincronizado
A19: SUBC. | B19: Jefe Especialista Tendido | C19: CTC_01 | D19: Ismael Dones | E19: No Iniciado | F19: No Iniciado | G19: No Iniciado | H19: No Iniciado | I19: N/A | J19: No Iniciado | K19: =COUNTIF(L19:R19,"*OK*") & " de 7 ; " & ROUND(COUNTIF(L19:R19,"*OK*")/7*100,0) & "%" -> 0 de 7 ; 0% | S19: No Iniciado | T19: No Iniciado | U19: No Iniciado | V19: No Iniciado | W19: No Iniciado | X19: No Iniciado | Y19: No Iniciado | Z19: No Iniciado | AA19: No Iniciado | AB19: No Iniciado | AC19: N/A | AD19: N/A | AE19: N/A | AF19: No Iniciado | AG19: N/A | AH19: N/A | AI19: =IFERROR(HDR_Matriz!BI19, "Pendiente datos") -> 0 | AJ19: =IFERROR((COUNTIF(S19:AH19, "Aprobado")) / (12 - COUNTIF(S19:AH19, "N/A")), "Pendiente datos") -> 0 | AK19: En proceso | AL19: =IFERROR(IF(AK19="Acreditado", "Verde", IF(AK19="En Proceso", "Amarillo", "Rojo")), "Pendiente datos") -> Amarillo | AM19: =IFERROR(AVERAGE(AJ19, AI19), "Pendiente datos") -> 0 | AN19: Sincronizado
A21: P18 | B21: Maestro 2° Líneas | C21: M2_03 | D21: Teodoro Paca | E21: Alterado | F21: Aprobado | G21: Aprobado | H21: Aprobado | I21: N/A | J21: Alterado | K21: =COUNTIF(L21:R21,"*OK*") & " de 7 ; " & ROUND(COUNTIF(L21:R21,"*OK*")/7*100,0) & "%" -> 2 de 7 ; 29% | L21: Obs. Bajo lo esperado | M21: OK -Dentro de lo esperado | N21: Obs. Bajo lo esperado | O21: Obs. Bajo lo esperado | P21: Obs. Bajo lo esperado | Q21: OK -Dentro de lo esperado | R21: Obs. Bajo lo esperado | S21: Alterado | T21: No Iniciado | U21: No Iniciado | V21: No Iniciado | W21: No Iniciado | X21: No Iniciado | Y21: No Iniciado | Z21: No Iniciado | AA21: No Iniciado | AB21: No Iniciado | AE21: N/A | AF21: No Iniciado | AH21: N/A | AI21: =IFERROR(HDR_Matriz!BI16, "Pendiente datos") -> 0 | AJ21: =IFERROR((COUNTIF(S21:AH21, "Aprobado")) / (12 - COUNTIF(S21:AH21, "N/A")), "Pendiente datos") -> 0 | AK21: En proceso | AL21: =IFERROR(IF(AK21="Acreditado", "Verde", IF(AK21="En Proceso", "Amarillo", "Rojo")), "Pendiente datos") -> Amarillo | AM21: =IFERROR(AVERAGE(AJ21, AI21), "Pendiente datos") -> 0 | AN21: Sincronizado
A22: P19 | B22: Rigger | C22: RIG_02 | D22: Christian Romero - Desiste | E22: No Iniciado | F22: No Iniciado | G22: No Iniciado | H22: No Iniciado | I22: N/A | J22: No Iniciado | K22: =COUNTIF(L22:R22,"*OK*") & " de 7 ; " & ROUND(COUNTIF(L22:R22,"*OK*")/7*100,0) & "%" -> 0 de 7 ; 0% | S22: No Iniciado | T22: No Iniciado | U22: No Iniciado | V22: No Iniciado | W22: No Iniciado | X22: No Iniciado | Y22: No Iniciado | Z22: No Iniciado | AA22: No Iniciado | AB22: No Iniciado | AE22: No Iniciado | AF22: No Iniciado | AH22: N/A | AI22: =IFERROR(HDR_Matriz!BI24, "Pendiente datos") -> 0 | AJ22: =IFERROR((COUNTIF(S22:AH22, "Aprobado")) / (12 - COUNTIF(S22:AH22, "N/A")), "Pendiente datos") -> 0 | AK22: En proceso | AL22: =IFERROR(IF(AK22="Acreditado", "Verde", IF(AK22="En Proceso", "Amarillo", "Rojo")), "Pendiente datos") -> Amarillo | AM22: =IFERROR(AVERAGE(AJ22, AI22), "Pendiente datos") -> 0 | AN22: Sincronizado
A23: P20 | B23: Alarife | C23: ALA_01 | D23: Javier Lucas | E23: Alterado | F23: Aprobado | G23: Alterado | H23: Alterado | I23: N/A | J23: Aprobado | K23: =COUNTIF(L23:R23,"*OK*") & " de 7 ; " & ROUND(COUNTIF(L23:R23,"*OK*")/7*100,0) & "%" -> 7 de 7 ; 100% | L23: OK -Dentro de lo esperado | M23: OK -Dentro de lo esperado | N23: OK -Dentro de lo esperado | O23: OK -Dentro de lo esperado | P23: OK -Dentro de lo esperado | Q23: OK -Dentro de lo esperado | R23: OK -Dentro de lo esperado | S23: No Iniciado | T23: No Iniciado | U23: No Iniciado | V23: No Iniciado | W23: No Iniciado | X23: No Iniciado | Y23: No Iniciado | Z23: No Iniciado | AA23: No Iniciado | AB23: No Iniciado | AE23: N/A | AF23: No Iniciado | AH23: N/A | AI23: =IFERROR(HDR_Matriz!BI24, "Pendiente datos") -> 0 | AJ23: =IFERROR((COUNTIF(S23:AH23, "Aprobado")) / (12 - COUNTIF(S23:AH23, "N/A")), "Pendiente datos") -> 0 | AK23: En proceso | AL23: =IFERROR(IF(AK23="Acreditado", "Verde", IF(AK23="En Proceso", "Amarillo", "Rojo")), "Pendiente datos") -> Amarillo | AM23: =IFERROR(AVERAGE(AJ23, AI23), "Pendiente datos") -> 0 | AN23: Sincronizado
A24: P21 | B24: Alarife | C24: ALA_02 | D24: Giovany Prandi | E24: Solicitado el 05-06-26 | F24: Solicitado el 05-06-27 | G24: Solicitado el 05-06-28 | H24: Solicitado el 05-06-29 | I24: N/A | J24: Solicitado el 05-06-29 | K24: =COUNTIF(L24:R24,"*OK*") & " de 7 ; " & ROUND(COUNTIF(L24:R24,"*OK*")/7*100,0) & "%" -> 7 de 7 ; 100% | L24: OK -Dentro de lo esperado | M24: OK -Dentro de lo esperado | N24: OK -Dentro de lo esperado | O24: OK -Dentro de lo esperado | P24: OK -Dentro de lo esperado | Q24: OK -Dentro de lo esperado | R24: OK -Dentro de lo esperado | S24: No Iniciado | T24: No Iniciado | U24: No Iniciado | V24: No Iniciado | W24: No Iniciado | X24: No Iniciado | Y24: No Iniciado | Z24: No Iniciado | AA24: No Iniciado | AB24: No Iniciado | AE24: N/A | AF24: No Iniciado | AH24: N/A | AI24: =IFERROR(HDR_Matriz!BI25, "Pendiente datos") -> 0 | AJ24: =IFERROR((COUNTIF(S24:AH24, "Aprobado")) / (12 - COUNTIF(S24:AH24, "N/A")), "Pendiente datos") -> 0 | AK24: En proceso | AL24: =IFERROR(IF(AK24="Acreditado", "Verde", IF(AK24="En Proceso", "Amarillo", "Rojo")), "Pendiente datos") -> Amarillo | AM24: =IFERROR(AVERAGE(AJ24, AI24), "Pendiente datos") -> 0 | AN24: Sincronizado

Sheet HDR_Matriz
A1: ID | B1: Cargo | C1: Nombre | D1: 1. IRL (DS.44) | E1: 2. Derecho detener trabajo | F1: 3. Inducción a riesgos | G1: 4. DDHH | H1: 5. Inducción Escondida | I1: 6. Intro a Gral IISS | J1: 7. Intro Zona Especifica | K1: 8. Cartilla Identificación | L1: 9. Obs. Preventivas | M1: 10. Liderazgo Terreno | N1: 11. Control critico | O1: 12. Auditoria Coaching | P1: 13. Inspecciones | Q1: 14. Aislamiento Bloqueo | R1: 15. Riesgo materiales | S1: 16. Procedimiento Emergencia | T1: 17. Reglas Cardinales | U1: 18. No en nuestro lugar | V1: 19. Preocupación Crónica | W1: 20. Politica Alcohol | X1: 21. Sustancias Peligrosas | Y1: 22. Nuestro Código | Z1: 23. Entrega RIOHS | AA1: 24. Entrega EPP | AB1: 25. Entrega Procedimiento | AC1: 26. Evaluación 3D | AD1: 27. Exámen Gran Altura | AE1: 28. Exámen Altura Fisica | AF1: 29. Contrato de trabajo | AG1: 30. Permiso Trabajo | AH1: 31. Protec. Respiratoria | AI1: 32. Espacio Confinado | AJ1: 33. Trabajo en caliente | AK1: 34. Alta tensión | AL1: 35. Control riesgos electricos | AM1: 36. Trabajo en altura | AN1: 37. Rescate en altura | AO1: 38. Armado andamios | AP1: 39. Riesgo Psicosocial | AQ1: 40. Hipobaria | AR1: 41. Protec. Auditiva | AS1: 42. Radiaciones UV | AT1: 43. Conciencia carcinógenos | AU1: 44. Primeros Auxilios | AV1: 45. Uso extintores | AW1: 46. Liderazgo en Terreno | AX1: 47. Manejo defensiva | AY1: 48. Examen Psicosensométrico | AZ1: 49. Hoja Vida conductor | BA1: 50. Licencia Municipal | BB1: 51. Operador Grúa | BC1: 52. Operador Equipos | BD1: 53. Operador andamios | BE1: 54. Eventos security | BF1: 55. Condiciones climáticas | BG1: 56. Riesgo caída rocas | BH1: Total Aplica | BI1: % Avance HDR
A2: P01 | B2: =+RRHH_Control!B2 -> Administrador Contrato | C2: =+RRHH_Control!D2 -> Andrés Tebes | D2: No Iniciado | E2: No Iniciado | F2: No Iniciado | G2: No Iniciado | H2: No Iniciado | I2: No Iniciado | J2: No Iniciado | K2: No Iniciado | L2: No Iniciado | M2: No Iniciado | N2: No Iniciado | O2: No Iniciado | P2: No Iniciado | Q2: No Iniciado | R2: No Iniciado | S2: No Iniciado | T2: No Iniciado | U2: No Iniciado | V2: No Iniciado | W2: No Iniciado | X2: No Iniciado | Y2: No Iniciado | Z2: No Iniciado | AA2: No Iniciado | AB2: No Iniciado | AC2: No Iniciado | AD2: No Iniciado | AE2: No Iniciado | AF2: No Iniciado | AG2: No Iniciado | AH2: No Iniciado | AI2: No Iniciado | AJ2: No Iniciado | AK2: No Iniciado | AL2: No Iniciado | AM2: No Iniciado | AN2: No Iniciado | AO2: No Iniciado | AP2: No Iniciado | AQ2: No Iniciado | AR2: No Iniciado | AS2: No Iniciado | AT2: No Iniciado | AU2: No Iniciado | AV2: No Iniciado | AW2: No Iniciado | AX2: No Iniciado | AY2: No Iniciado | AZ2: No Iniciado | BA2: No Iniciado | BB2: No Iniciado | BC2: No Iniciado | BD2: No Iniciado | BE2: No Iniciado | BF2: No Iniciado | BG2: No Iniciado | BH2: =IFERROR(56 - COUNTIF(D2:BG2, "N/A"), "Pendiente datos") -> 56 | BI2: =IFERROR(COUNTIF(D2:BG2, "Aprobado") / BH2, "Pendiente datos") -> 0
A3: P02 | B3: =+RRHH_Control!B3 -> Asesor de Seguridad | C3: =+RRHH_Control!D3 -> Juan Carlos Santander | D3: No Iniciado | E3: No Iniciado | F3: No Iniciado | G3: No Iniciado | H3: No Iniciado | I3: No Iniciado | J3: No Iniciado | K3: No Iniciado | L3: No Iniciado | M3: No Iniciado | N3: No Iniciado | O3: No Iniciado | P3: No Iniciado | Q3: No Iniciado | R3: No Iniciado | S3: No Iniciado | T3: No Iniciado | U3: No Iniciado | V3: No Iniciado | W3: No Iniciado | X3: No Iniciado | Y3: No Iniciado | Z3: No Iniciado | AA3: No Iniciado | AB3: No Iniciado | AC3: No Iniciado | AD3: No Iniciado | AE3: No Iniciado | AF3: No Iniciado | AG3: No Iniciado | AH3: No Iniciado | AI3: No Iniciado | AJ3: No Iniciado | AK3: No Iniciado | AL3: No Iniciado | AM3: No Iniciado | AN3: No Iniciado | AO3: No Iniciado | AP3: No Iniciado | AQ3: No Iniciado | AR3: No Iniciado | AS3: No Iniciado | AT3: No Iniciado | AU3: No Iniciado | AV3: No Iniciado | AW3: No Iniciado | AX3: No Iniciado | AY3: No Iniciado | AZ3: No Iniciado | BA3: No Iniciado | BB3: No Iniciado | BC3: No Iniciado | BD3: No Iniciado | BE3: No Iniciado | BF3: No Iniciado | BG3: No Iniciado | BH3: =IFERROR(56 - COUNTIF(D3:BG3, "N/A"), "Pendiente datos") -> 56 | BI3: =IFERROR(COUNTIF(D3:BG3, "Aprobado") / BH3, "Pendiente datos") -> 0
